Workbook

Sheet Guia_Utilização
A1: 📖 GUIA DE UTILIZAÇÃO — SISTEMA DE MONITORIZAÇÃO DE CARGA | Belenenses
A3: 1 — ESTRUTURA DO MODELO
A5: Folha | B5: Tab | C5: Função | D5: Seletores / Inputs
A6: Plantel | B6: 🟠 | C6: Lista mestre de jogadores. Gere estado (Ativo/Lesionado), posição e dados pessoais. Alimenta Input_Diário automaticamente. | D6: Jogador, Posição, Estado, Nº Camisola, Data Nascimento
A7: Input_Diário | B7: 🟠 | C7: Registo diário de dados GPS, PSE e Wellness (Hooper Index). Preencher após cada sessão. | D7: Data, MC#, Tipo, Dia MD + métricas GPS + PSE + Fadiga + Min Jogo + Sono + Dor Musc. + Stress + Humor
A8: Painel_Central | B8: 🟢 | C8: Dashboard executivo com risco por jogador, ACWR (4MC), Hooper Index, congestão, tendência CI, e resumo de equipa. | D8: Nenhum (automático)
A9: Carga_Planeada | B9: 🟠 | C9: Compara carga real vs esperada por dia MD. Desvios % por jogador. | D9: Microciclo (B13), Dia MD (E13)
A10: BD_Carga | B10: 🟦 | C10: Base de dados principal (tblCarga). Colunas T-V: Fadiga, Min Jogo, Congestão. Colunas W-AA: Sono, Dor Musc., Stress, Humor, Hooper Index. | D10: Adicionar linhas no final da tabela
A11: ACWR_EWMA | B11: 🟦 | C11: Rácio Agudo:Crónico (EWMA) para carga externa e interna. | D11: Jogador (B5)
A12: Monot_Strain | B12: 🟦 | C12: Monotonia e Strain semanal por jogador. | D12: Jogador (B5)
A13: Vmáx_Monitor | B13: 🟦 | C13: Monitorização de velocidade máxima e limiares ≥85/90/95%. | D13: Jogador secção B (B19)
A14: Dash_Treino | B14: 🟢 | C14: Dashboard individual com KPIs, histórico completo e evolução por microciclo (CI, Dist, HSR, Sprint, Vmáx). | D14: Jogador (B4)
A15: Dash_Gráficos | B15: 🟢 | C15: Gráficos de sessão com data bars por jogador. | D15: Microciclo (B4), Dia MD (D4)
A16: Dash_Posição | B16: 🟢 | C16: Comparação de métricas entre jogadores da mesma posição. | D16: Posição (B3)
... A19: Dash_Microciclos | B19: 🟢 | C19: Comparação entre microciclos (médias, deltas, jogo vs treino). | D19: Nenhum (automático)
A21: 2 — COMO REGISTAR DADOS
A23: Passo | B23: Ação
A24: 1️⃣ | B24: Abrir a folha Input_Diário
A25: 2️⃣ | B25: Preencher Data (B5), Microciclo (E5), Tipo de sessão (H5), e Dia MD (K5)
A26: 3️⃣ | B26: Preencher as células amarelas (C8:T32) com GPS, PSE, Fadiga, Min Jogo e Wellness (Sono, Dor, Stress, Humor)
A27: 4️⃣ | B27: Verificar a seção de transferência (linhas 37+) — os dados estão organizados para colar na BD_Carga
A28: 5️⃣ | B28: Copiar as linhas de transferência A38:Z?? (valores, não fórmulas) e colar no final da tabela tblCarga em BD_Carga
A29: 6️⃣ | B29: Limpar as células amarelas do Input_Diário para a próxima sessão
A31: ⚠️ A tabela tblCarga (BD_Carga) é a fonte de TODOS os dashboards. Não apagues linhas sem cuidado!
A33: 3 — INTERPRETAÇÃO DOS ALERTAS
A35: Código | B35: Significado | C35: Ação Recomendada
A36: 🟢 OK | B36: ACWR 0.8–1.3 | Monotonia <2 | Vmáx ≥90% recente | C36: Carga adequada. Manter plano.
A37: 🟡 ATENÇÃO | B37: ACWR 1.3–1.5 ou <0.8 | Monotonia 2–2.5 | 8–14 dias sem ≥90% | C37: Monitorizar de perto. Considerar ajustar volume/intensidade.
A38: 🔴 RISCO | B38: ACWR >1.5 | Monotonia >2.5 | >14 dias sem ≥90% Vmáx | Strain >3000 | C38: Reduzir carga imediatamente. Consultar staff médico.
A39: 🟦 SUB-CARGA | B39: Z-score < -2.0 | ACWR < 0.6 | Desvio < -25% | C39: Jogador significativamente abaixo da equipa. Avaliar razão (lesão? recuperação?).
A41: 4 — METODOLOGIA
A43: Métrica | B43: Fórmula | C43: Referência
A44: Carga Interna (CI) | B44: PSE Sessão × Duração (min) | C44: Foster et al. (2001)
A45: ACWR (EWMA) | B45: λ aguda = 2/(7+1) = 0.25 | λ crónica = 2/(28+1) ≈ 0.069 | ACWR = Aguda/Crónica | C45: Williams et al. (2017)
A46: Monotonia | B46: Média Semanal CI ÷ Desvio Padrão Semanal CI | C46: Foster (1998)
A47: Strain | B47: Carga Semanal Total CI × Monotonia | C47: Foster (1998)
A48: Z-Score | B48: (Média Jogador − Média Equipa) ÷ Desvio Padrão Equipa | C48: Contextualização individual
A49: % Vmáx Record | B49: Vel. Sessão ÷ Vmáx Histórico do Jogador × 100 | C49: Monitorização de exposição à alta velocidade
A51: 5 — NOTAS IMPORTANTES
A53: • As folhas de dashboard estão protegidas. Só os seletores (células azuis/amarelas) são editáveis.
...

Sheet Plantel
A1: 🏟️ PLANTEL — Lista Mestre de Jogadores
A3: Jogador | B3: Posição | C3: Estado | D3: Nº Camisola | E3: Data Nascimento | G3: 📖 INSTRUÇÕES
A4: Artur | B4: Médio | C4: Ativo | G4: • Adiciona jogadores nesta lista (máx 30)
A5: Capitulo | B5: Lateral | C5: Ativo | G5: • O Input_Diário puxa automaticamente os jogadores 'Ativos'
A6: Edu | B6: Lateral | C6: Ativo | G6: • Muda 'Estado' para Lesionado/Emprestado para excluir
A7: Enzo Hugo | B7: Central | C7: Ativo | G7: • A ordem aqui define a ordem no Input e Painel Central
A8: Gomes | B8: Médio | C8: Ativo
A9: Nogueira | B9: Central | C9: Ativo
A10: Paulino | B10: Médio | C10: Ativo
A11: Sá | B11: Médio | C11: Ativo
A12: Varela | B12: Lateral | C12: Ativo
A13: Valente | B13: Extremo | C13: Ativo
A14: Quinalau | B14: Avançado | C14: Ativo
A15: Bruno | B15: Guarda-Redes | C15: Ativo

Sheet BD_Carga
A1: 📋 BASE DE DADOS — REGISTO DE CARGA | Belenenses
A2: Data | B2: Equipa | C2: Jogador | D2: Posição | E2: Duração (min) | F2: Distância Total (m) | G2: HSR (m) | H2: Sprint (m) | I2: Acc (n) | J2: Dcc (n) | K2: PSE Sessão | L2: Vel. Máx (km/h) | M2: Microciclo | N2: Nº ≥85% Vmáx | O2: Nº ≥90% Vmáx | P2: Nº ≥95% Vmáx | Q2: Tipo | R2: Microciclo (Nr) | S2: Dia MD | T2: Fadiga (1-5) | U2: Min Jogo | V2: Congestão (dias) | W2: Sono (1-5) | X2: Dor Musc. (1-5) | Y2: Stress (1-5) | Z2: Humor (1-5) | AA2: Hooper Index
A3: 46045 | B3: Belenenses | C3: Paulino | D3: Médio | E3: 88 | F3: 6690 | G3: 265 | H3: 136 | I3: 76 | J3: 72 | K3: 6 | L3: 30.3 | M3: 4 | N3: 11 | O3: 3 | P3: 1 | Q3: Treino | R3: 4 | S3: MD-2 | V3: =IF(_xlfn.MAXIFS(tblCarga[Data],tblCarga[Jogador],C3,tblCarga[Tipo],"Jogo",tblCarga[Data],"<"&A3)=0,"-",A3-_xlfn.MAXIFS(tblCarga[Data],tblCarga[Jogador],C3,tblCarga[Tipo],"Jogo",tblCarga[Data],"<"&A3)) | W3: 2 | X3: 3 | Y3: 1 | Z3: 3 | AA3: 9
A4: 46045 | B4: Belenenses | C4: Artur | D4: Médio | E4: 90 | F4: 9262 | G4: 199 | H4: 48 | I4: 83 | J4: 80 | K4: 8 | L4: 29.8 | M4: 4 | N4: 10 | O4: 6 | P4: 3 | Q4: Treino | R4: 4 | S4: MD-2 | V4: =IF(_xlfn.MAXIFS(tblCarga[Data],tblCarga[Jogador],C4,tblCarga[Tipo],"Jogo",tblCarga[Data],"<"&A4)=0,"-",A4-_xlfn.MAXIFS(tblCarga[Data],tblCarga[Jogador],C4,tblCarga[Tipo],"Jogo",tblCarga[Data],"<"&A4)) | W4: 2 | X4: 1 | Y4: 3 | Z4: 1 | AA4: 7
A5: 46045 | B5: Belenenses | C5: Gomes | D5: Médio | E5: 87 | F5: 10123 | G5: 218 | H5: 105 | I5: 90 | J5: 84 | K5: 9 | L5: 29 | M5: 4 | N5: 12 | O5: 4 | P5: 2 | Q5: Treino | R5: 4 | S5: MD-2 | V5: =IF(_xlfn.MAXIFS(tblCarga[Data],tblCarga[Jogador],C5,tblCarga[Tipo],"Jogo",tblCarga[Data],"<"&A5)=0,"-",A5-_xlfn.MAXIFS(tblCarga[Data],tblCarga[Jogador],C5,tblCarga[Tipo],"Jogo",tblCarga[Data],"<"&A5)) | W5: 3 | X5: 3 | Y5: 1 | Z5: 1 | AA5: 8
A6: 46045 | B6: Belenenses | C6: Sá | D6: Médio | E6: 94 | F6: 8899 | G6: 289 | H6: 45 | I6: 65 | J6: 80 | K6: 10 | L6: 31.1 | M6: 4 | N6: 13 | O6: 7 | P6: 1 | Q6: Treino | R6: 4 | S6: MD-2 | V6: =IF(_xlfn.MAXIFS(tblCarga[Data],tblCarga[Jogador],C6,tblCarga[Tipo],"Jogo",tblCarga[Data],"<"&A6)=0,"-",A6-_xlfn.MAXIFS(tblCarga[Data],tblCarga[Jogador],C6,tblCarga[Tipo],"Jogo",tblCarga[Data],"<"&A6)) | W6: 2 | X6: 3 | Y6: 1 | Z6: 2 | AA6: 8
A7: 46045 | B7: Belenenses | C7: Varela | D7: Lateral | E7: 89 | F7: 11440 | G7: 363 | H7: 175 | I7: 75 | J7: 80 | K7: 8 | L7: 32.3 | M7: 4 | N7: 6 | O7: 3 | P7: 1 | Q7: Treino | R7: 4 | S7: MD-2 | V7: =IF(_xlfn.MAXIFS(tblCarga[Data],tblCarga[Jogador],C7,tblCarga[Tipo],"Jogo",tblCarga[Data],"<"&A7)=0,"-",A7-_xlfn.MAXIFS(tblCarga[Data],tblCarga[Jogador],C7,tblCarga[Tipo],"Jogo",tblCarga[Data],"<"&A7)) | W7: 2 | X7: 2 | Y7: 2 | Z7: 2 | AA7: 8
A8: 46045 | B8: Belenenses | C8: Edu | D8: Lateral | E8: 95 | F8: 11377 | G8: 469 | H8: 231 | I8: 84 | J8: 75 | K8: 4 | L8: 31.9 | M8: 4 | N8: 12 | O8: 5 | P8: 2 | Q8: Treino | R8: 4 | S8: MD-2 | V8: =IF(_xlfn.MAXIFS(tblCarga[Data],tblCarga[Jogador],C8,tblCarga[Tipo],"Jogo",tblCarga[Data],"<"&A8)=0,"-",A8-_xlfn.MAXIFS(tblCarga[Data],tblCarga[Jogador],C8,tblCarga[Tipo],"Jogo",tblCarga[Data],"<"&A8)) | W8: 1 | X8: 2 | Y8: 2 | Z8: 3 | AA8: 8
A9: 46045 | B9: Belenenses | C9: Capitulo | D9: Lateral | E9: 95 | F9: 10190 | G9: 486 | H9: 170 | I9: 83 | J9: 82 | K9: 4 | L9: 31 | M9: 4 | N9: 11 | O9: 7 | P9: 1 | Q9: Treino | R9: 4 | S9: MD-2 | V9: =IF(_xlfn.MAXIFS(tblCarga[Data],tblCarga[Jogador],C9,tblCarga[Tipo],"Jogo",tblCarga[Data],"<"&A9)=0,"-",A9-_xlfn.MAXIFS(tblCarga[Data],tblCarga[Jogador],C9,tblCarga[Tipo],"Jogo",tblCarga[Data],"<"&A9)) | W9: 2 | X9: 1 | Y9: 1 | Z9: 3 | AA9: 7
A10: 46045 | B10: Belenenses | C10: Enzo Hugo | D10: Central | E10: 84 | F10: 9489 | G10: 251 | H10: 44 | I10: 82 | J10: 96 | K10: 8 | L10: 28.7 | M10: 4 | N10: 13 | O10: 7 | P10: 4 | Q10: Treino | R10: 4 | S10: MD-2 | V10: =IF(_xlfn.MAXIFS(tblCarga[Data],tblCarga[Jogador],C10,tblCarga[Tipo],"Jogo",tblCarga[Data],"<"&A10)=0,"-",A10-_xlfn.MAXIFS(tblCarga[Data],tblCarga[Jogador],C10,tblCarga[Tipo],"Jogo",tblCarga[Data],"<"&A10)) | W10: 2 | X10: 2 | Y10: 2 | Z10: 2 | AA10: 8
A11: 46045 | B11: Belenenses | C11: Nogueira | D11: Central | E11: 93 | F11: 10367 | G11: 303 | H11: 33 | I11: 62 | J11: 87 | K11: 7 | L11: 28.8 | M11: 4 | N11: 9 | O11: 5 | P11: 3 | Q11: Treino | R11: 4 | S11: MD-2 | V11: =IF(_xlfn.MAXIFS(tblCarga[Data],tblCarga[Jogador],C11,tblCarga[Tipo],"Jogo",tblCarga[Data],"<"&A11)=0,"-",A11-_xlfn.MAXIFS(tblCarga[Data],tblCarga[Jogador],C11,tblCarga[Tipo],"Jogo",tblCarga[Data],"<"&A11)) | W11: 2 | X11: 2 | Y11: 2 | Z11: 3 | AA11: 9
A12: 46052 | B12: Belenenses | C12: Paulino | D12: Médio | E12: 82 | F12: 6537 | G12: 264 | H12: 132 | I12: 61 | J12: 71 | K12: 7 | L12: 30.5 | M12: 5 | N12: 13 | O12: 8 | P12: 4 | Q12: Treino | R12: 5 | S12: MD-1 | V12: =IF(_xlfn.MAXIFS(tblCarga[Data],tblCarga[Jogador],C12,tblCarga[Tipo],"Jogo",tblCarga[Data],"<"&A12)=0,"-",A12-_xlfn.MAXIFS(tblCarga[Data],tblCarga[Jogador],C12,tblCarga[Tipo],"Jogo",tblCarga[Data],"<"&A12)) | W12: 1 | X12: 1 | Y12: 2 | Z12: 2 | AA12: 6
A13: 46052 | B13: Belenenses | C13: Artur | D13: Médio | E13: 95 | F13: 8996 | G13: 172 | H13: 55 | I13: 70 | J13: 76 | K13: 6 | L13: 30.2 | M13: 5 | N13: 10 | O13: 5 | P13: 2 | Q13: Treino | R13: 5 | S13: MD-1 | V13: =IF(_xlfn.MAXIFS(tblCarga[Data],tblCarga[Jogador],C13,tblCarga[Tipo],"Jogo",tblCarga[Data],"<"&A13)=0,"-",A13-_xlfn.MAXIFS(tblCarga[Data],tblCarga[Jogador],C13,tblCarga[Tipo],"Jogo",tblCarga[Data],"<"&A13)) | W13: 1 | X13: 1 | Y13: 2 | Z13: 1 | AA13: 5
A14: 46052 | B14: Belenenses | C14: Gomes | D14: Médio | E14: 81 | F14: 8529 | G14: 240 | H14: 111 | I14: 77 | J14: 87 | K14: 7 | L14: 28.3 | M14: 5 | N14: 9 | O14: 3 | P14: 1 | Q14: Treino | R14: 5 | S14: MD-1 | V14: =IF(_xlfn.MAXIFS(tblCarga[Data],tblCarga[Jogador],C14,tblCarga[Tipo],"Jogo",tblCarga[Data],"<"&A14)=0,"-",A14-_xlfn.MAXIFS(tblCarga[Data],tblCarga[Jogador],C14,tblCarga[Tipo],"Jogo",tblCarga[Data],"<"&A14)) | W14: 2 | X14: 2 | Y14: 1 | Z14: 1 | AA14: 6
... A470: 46138 | B470: Belenenses | C470: Nogueira | D470: Central | E470: 57 | F470: 5646 | G470: 136 | H470: 9 | I470: 32 | J470: 45 | K470: 2 | L470: 25 | M470: 10 | N470: 5 | O470: 2 | P470: 0 | Q470: Treino | R470: 10 | S470: MD-1 | V470: =IF(_xlfn.MAXIFS(tblCarga[Data],tblCarga[Jogador],C470,tblCarga[Tipo],"Jogo",tblCarga[Data],"<"&A470)=0,"-",A470-_xlfn.MAXIFS(tblCarga[Data],tblCarga[Jogador],C470,tblCarga[Tipo],"Jogo",tblCarga[Data],"<"&A470)) | W470: 1 | X470: 1 | Y470: 2 | Z470: 1 | AA470: 5

Sheet Painel_Central
A1: 🏆 PAINEL CENTRAL | Belenenses | G1: MC: | H1: 10
A3: 🔴 | B3: =COUNTIF($C$8:$C$32,"🔴") | C3: Risco | D3: 🟡 | E3: =COUNTIF($C$8:$C$32,"🟡") | F3: Atenção | G3: 🟢 | H3: =COUNTIF($C$8:$C$32,"🟢") | I3: OK | J3: Equipa: | K3: =COUNTIF($C$8:$C$32,"🔴")&"🔴 "&COUNTIF($C$8:$C$32,"🟡")&"🟡 "&COUNTIF($C$8:$C$32,"🟢")&"🟢"
A5: ▬▬▬ ESTADO POR JOGADOR ▬▬▬▬▬▬▬▬▬▬▬▬▬▬▬▬▬▬▬▬▬▬▬▬▬▬▬▬▬▬▬▬▬▬▬▬▬▬▬▬▬▬▬▬▬▬▬▬▬▬▬▬▬▬▬▬▬▬▬▬
A7: # | B7: Jogador | C7: Estado | D7: Risco (1-10) | E7: Motivo Principal | F7: Δ Carga | G7: ACWR (EWMA) | H7: Monot. | I7: Dias s/ ≥90% | J7: CI Sem. (MC atual) | K7: Min. Jogo (último MC) | L7: Jogos Consec. | M7: Ação Recomendada | N7: Tendência CI (4MC) | O7: Hooper (último) | P7: MC-3 | Q7: MC-2 | R7: MC-1 | S7: MC atual | T7: Congestão (dias)
A8: =IF(B8="","",ROW()-7) | B8: {=IFERROR(IF(INDEX(_xlfn._xlws.SORT(_xlfn.UNIQUE(tblCarga[Jogador])),ROW()-7)=0,"",INDEX(_xlfn._xlws.SORT(_xlfn.UNIQUE(tblCarga[Jogador])),ROW()-7)),"")} | C8: =IF(B8="","",IF(D8>=7,"🔴",IF(D8>=4,"🟡","🟢"))) | D8: =IF(B8="","",_xlfn.LET(_xlpm.acwr,G8,_xlpm.monot,H8,_xlpm.dias,I8,_xlpm.tend,F8,_xlpm.cong,T8,_xlpm.hooper,O8,_xlpm.rACWR,IF(_xlpm.acwr="—",0,IF(OR(_xlpm.acwr>1.5,_xlpm.acwr<0.6),3,IF(OR(_xlpm.acwr>1.3,_xlpm.acwr<0.8),2,IF(_xlpm.acwr<=1.1,0.5,0)))),_xlpm.rMonot,IF(_xlpm.monot>2.5,3,IF(_xlpm.monot>2,2,IF(_xlpm.monot>1.5,1,0))),_xlpm.rDias,IF(_xlpm.dias>14,3,IF(_xlpm.dias>7,2,IF(_xlpm.dias>5,1,0))),_xlpm.rTend,IF(AND(_xlpm.tend="↑",_xlpm.acwr>1.1),1,0),_xlpm.rCong,IF(AND(_xlpm.cong<>"—",_xlpm.cong<4),2,IF(AND(_xlpm.cong<>"—",_xlpm.cong<=5),1,0)),_xlpm.rHooper,IF(AND(_xlpm.hooper<>"—",_xlpm.hooper>=15),1,0),MIN(10,ROUND(_xlpm.rACWR+_xlpm.rMonot+_xlpm.rDias+_xlpm.rTend+_xlpm.rCong+_xlpm.rHooper,0)))) | E8: =IF(B8="","",IF(D8<4,"✅ Sem alertas",_xlfn.LET(_xlpm.acwr,G8,_xlpm.monot,H8,_xlpm.dias,I8,_xlpm.reasons,IF(AND(_xlpm.acwr<>"—",OR(_xlpm.acwr>1.3,_xlpm.acwr<0.8)),"ACWR "&ROUND(_xlpm.acwr,2),"")&IF(AND(_xlpm.monot>2,AND(_xlpm.acwr<>"—",OR(_xlpm.acwr>1.3,_xlpm.acwr<0.8)))," | ","")&IF(_xlpm.monot>2,"Monot "&ROUND(_xlpm.monot,1),"")&IF(AND(_xlpm.dias>7,OR(AND(_xlpm.acwr<>"—",OR(_xlpm.acwr>1.3,_xlpm.acwr<0.8)),_xlpm.monot>2))," | ","")&IF(_xlpm.dias>7,"Vmáx "&_xlpm.dias&"d",""),IF(LEN(_xlpm.reasons)>0,_xlpm.reasons,"Múltiplos fatores")))) | F8: {=IF(B8="","",IFERROR(_xlfn.LET(_xlpm.cur,J8,_xlpm.prev,SUMPRODUCT((tblCarga[Jogador]=B8)*(tblCarga[Microciclo (Nr)]=($H$1-1))*(tblCarga[Tipo]="Treino")*tblCarga[PSE Sessão]*tblCarga[Duração (min)]),_xlpm.delta,(_xlpm.cur-_xlpm.prev)/IF(_xlpm.prev=0,1,_xlpm.prev),IF(_xlpm.delta>0.1,"↑",IF(_xlpm.delta<-0.1,"↓","→"))),"—"))} | G8: =IF(B8="","",IFERROR(J8/(P8*0.4+Q8*0.3+R8*0.2+J8*0.1),"—")) | H8: =IF(B8="","",IFERROR(INDEX(Monot_Strain!F$9:F$38,MATCH(B8,Monot_Strain!A$9:A$38,0)),0)) | I8: {=IF(B8="","",IFERROR(TODAY()-MAX(_xlfn._xlws.FILTER(tblCarga[Data],(tblCarga[Jogador]=B8)*(tblCarga[Nº ≥90% Vmáx]>0))),999))} | J8: {=IF(B8="","",SUMPRODUCT((tblCarga[Jogador]=B8)*(tblCarga[Microciclo (Nr)]=$H$1)*(tblCarga[Tipo]="Treino")*tblCarga[PSE Sessão]*tblCarga[Duração (min)]))} | K8: {=IF(B8="","",IFERROR(SUMPRODUCT((tblCarga[Jogador]=B8)*(tblCarga[Microciclo (Nr)]=$H$1)*(tblCarga[Tipo]="Jogo")*tblCarga[Duração (min)]),0))} | L8: {=IF(B8="","",IFERROR(_xlfn.LET(_xlpm.mcs,_xlfn._xlws.SORT(_xlfn.UNIQUE(_xlfn._xlws.FILTER(tblCarga[Microciclo (Nr)],(tblCarga[Jogador]=B8)*(tblCarga[Tipo]="Jogo"))),,,-1),_xlpm.curMC,$H$1,_xlpm.streak,0,IF(ROWS(_xlpm.mcs)=0,0,SUMPRODUCT(--(_xlpm.mcs>=_xlpm.curMC-ROWS(_xlpm.mcs)+1),--(_xlpm.mcs<=_xlpm.curMC)))),0))} | M8: =IF(B8="","",IF(D8>=7,"⚠️ Reduzir carga. Consultar staff médico.",IF(D8>=4,"🔍 Monitorizar. Ajustar volume se necessário.","✅ Manter plano de treino."))) | N8: =IF(B8="","",IF(S8>R8,"▲ "&ROUND(J8,0),IF(S8<R8,"▼ "&ROUND(J8,0),"→ "&ROUND(J8,0)))) | O8: {=IF(B8="","",IFERROR(INDEX(tblCarga[Hooper Index],MATCH(1,(tblCarga[Jogador]=B8)*(tblCarga[Data]=_xlfn.MAXIFS(tblCarga[Data],tblCarga[Jogador],B8,tblCarga[Hooper Index],">0")),0)),"—"))} | P8: {=IF(B8="","",SUMPRODUCT((tblCarga[Jogador]=B8)*(tblCarga[Microciclo (Nr)]=($H$1-3))*(tblCarga[Tipo]="Treino")*tblCarga[PSE Sessão]*tblCarga[Duração (min)]))} | Q8: {=IF(B8="","",SUMPRODUCT((tblCarga[Jogador]=B8)*(tblCarga[Microciclo (Nr)]=($H$1-2))*(tblCarga[Tipo]="Treino")*tblCarga[PSE Sessão]*tblCarga[Duração (min)]))} | R8: {=IF(B8="","",SUMPRODUCT((tblCarga[Jogador]=B8)*(tblCarga[Microciclo (Nr)]=($H$1-1))*(tblCarga[Tipo]="Treino")*tblCarga[PSE Sessão]*tblCarga[Duração (min)]))} | S8: =J8 | T8: =IF(B8="","",IFERROR(TODAY()-_xlfn.MAXIFS(tblCarga[Data],tblCarga[Jogador],B8,tblCarga[Tipo],"Jogo"),"—"))
A9: =IF(B9="","",ROW()-7) | B9: {=IFERROR(IF(INDEX(_xlfn._xlws.SORT(_xlfn.UNIQUE(tblCarga[Jogador])),ROW()-7)=0,"",INDEX(_xlfn._xlws.SORT(_xlfn.UNIQUE(tblCarga[Jogador])),ROW()-7)),"")} | C9: =IF(B9="","",IF(D9>=7,"🔴",IF(D9>=4,"🟡","🟢"))) | D9: =IF(B9="","",_xlfn.LET(_xlpm.acwr,G9,_xlpm.monot,H9,_xlpm.dias,I9,_xlpm.tend,F9,_xlpm.cong,T9,_xlpm.hooper,O9,_xlpm.rACWR,IF(_xlpm.acwr="—",0,IF(OR(_xlpm.acwr>1.5,_xlpm.acwr<0.6),3,IF(OR(_xlpm.acwr>1.3,_xlpm.acwr<0.8),2,IF(_xlpm.acwr<=1.1,0.5,0)))),_xlpm.rMonot,IF(_xlpm.monot>2.5,3,IF(_xlpm.monot>2,2,IF(_xlpm.monot>1.5,1,0))),_xlpm.rDias,IF(_xlpm.dias>14,3,IF(_xlpm.dias>7,2,IF(_xlpm.dias>5,1,0))),_xlpm.rTend,IF(AND(_xlpm.tend="↑",_xlpm.acwr>1.1),1,0),_xlpm.rCong,IF(AND(_xlpm.cong<>"—",_xlpm.cong<4),2,IF(AND(_xlpm.cong<>"—",_xlpm.cong<=5),1,0)),_xlpm.rHooper,IF(AND(_xlpm.hooper<>"—",_xlpm.hooper>=15),1,0),MIN(10,ROUND(_xlpm.rACWR+_xlpm.rMonot+_xlpm.rDias+_xlpm.rTend+_xlpm.rCong+_xlpm.rHooper,0)))) | E9: =IF(B9="","",IF(D9<4,"✅ Sem alertas",_xlfn.LET(_xlpm.acwr,G9,_xlpm.monot,H9,_xlpm.dias,I9,_xlpm.reasons,IF(AND(_xlpm.acwr<>"—",OR(_xlpm.acwr>1.3,_xlpm.acwr<0.8)),"ACWR "&ROUND(_xlpm.acwr,2),"")&IF(AND(_xlpm.monot>2,AND(_xlpm.acwr<>"—",OR(_xlpm.acwr>1.3,_xlpm.acwr<0.8)))," | ","")&IF(_xlpm.monot>2,"Monot "&ROUND(_xlpm.monot,1),"")&IF(AND(_xlpm.dias>7,OR(AND(_xlpm.acwr<>"—",OR(_xlpm.acwr>1.3,_xlpm.acwr<0.8)),_xlpm.monot>2))," | ","")&IF(_xlpm.dias>7,"Vmáx "&_xlpm.dias&"d",""),IF(LEN(_xlpm.reasons)>0,_xlpm.reasons,"Múltiplos fatores")))) | F9: {=IF(B9="","",IFERROR(_xlfn.LET(_xlpm.cur,J9,_xlpm.prev,SUMPRODUCT((tblCarga[Jogador]=B9)*(tblCarga[Microciclo (Nr)]=($H$1-1))*(tblCarga[Tipo]="Treino")*tblCarga[PSE Sessão]*tblCarga[Duração (min)]),_xlpm.delta,(_xlpm.cur-_xlpm.prev)/IF(_xlpm.prev=0,1,_xlpm.prev),IF(_xlpm.delta>0.1,"↑",IF(_xlpm.delta<-0.1,"↓","→"))),"—"))} | G9: =IF(B9="","",IFERROR(J9/(P9*0.4+Q9*0.3+R9*0.2+J9*0.1),"—")) | H9: =IF(B9="","",IFERROR(INDEX(Monot_Strain!F$9:F$38,MATCH(B9,Monot_Strain!A$9:A$38,0)),0)) | I9: {=IF(B9="","",IFERROR(TODAY()-MAX(_xlfn._xlws.FILTER(tblCarga[Data],(tblCarga[Jogador]=B9)*(tblCarga[Nº ≥90% Vmáx]>0))),999))} | J9: {=IF(B9="","",SUMPRODUCT((tblCarga[Jogador]=B9)*(tblCarga[Microciclo (Nr)]=$H$1)*(tblCarga[Tipo]="Treino")*tblCarga[PSE Sessão]*tblCarga[Duração (min)]))} | K9: {=IF(B9="","",IFERROR(SUMPRODUCT((tblCarga[Jogador]=B9)*(tblCarga[Microciclo (Nr)]=$H$1)*(tblCarga[Tipo]="Jogo")*tblCarga[Duração (min)]),0))} | L9: {=IF(B9="","",IFERROR(_xlfn.LET(_xlpm.mcs,_xlfn._xlws.SORT(_xlfn.UNIQUE(_xlfn._xlws.FILTER(tblCarga[Microciclo (Nr)],(tblCarga[Jogador]=B9)*(tblCarga[Tipo]="Jogo"))),,,-1),_xlpm.curMC,$H$1,_xlpm.streak,0,IF(ROWS(_xlpm.mcs)=0,0,SUMPRODUCT(--(_xlpm.mcs>=_xlpm.curMC-ROWS(_xlpm.mcs)+1),--(_xlpm.mcs<=_xlpm.curMC)))),0))} | M9: =IF(B9="","",IF(D9>=7,"⚠️ Reduzir carga. Consultar staff médico.",IF(D9>=4,"🔍 Monitorizar. Ajustar volume se necessário.","✅ Manter plano de treino."))) | N9: =IF(B9="","",IF(S9>R9,"▲ "&ROUND(J9,0),IF(S9<R9,"▼ "&ROUND(J9,0),"→ "&ROUND(J9,0)))) | O9: {=IF(B9="","",IFERROR(INDEX(tblCarga[Hooper Index],MATCH(1,(tblCarga[Jogador]=B9)*(tblCarga[Data]=_xlfn.MAXIFS(tblCarga[Data],tblCarga[Jogador],B9,tblCarga[Hooper Index],">0")),0)),"—"))} | P9: {=IF(B9="","",SUMPRODUCT((tblCarga[Jogador]=B9)*(tblCarga[Microciclo (Nr)]=($H$1-3))*(tblCarga[Tipo]="Treino")*tblCarga[PSE Sessão]*tblCarga[Duração (min)]))} | Q9: {=IF(B9="","",SUMPRODUCT((tblCarga[Jogador]=B9)*(tblCarga[Microciclo (Nr)]=($H$1-2))*(tblCarga[Tipo]="Treino")*tblCarga[PSE Sessão]*tblCarga[Duração (min)]))} | R9: {=IF(B9="","",SUMPRODUCT((tblCarga[Jogador]=B9)*(tblCarga[Microciclo (Nr)]=($H$1-1))*(tblCarga[Tipo]="Treino")*tblCarga[PSE Sessão]*tblCarga[Duração (min)]))} | S9: =J9 | T9: =IF(B9="","",IFERROR(TODAY()-_xlfn.MAXIFS(tblCarga[Data],tblCarga[Jogador],B9,tblCarga[Tipo],"Jogo"),"—"))
A10: =IF(B10="","",ROW()-7) | B10: {=IFERROR(IF(INDEX(_xlfn._xlws.SORT(_xlfn.UNIQUE(tblCarga[Jogador])),ROW()-7)=0,"",INDEX(_xlfn._xlws.SORT(_xlfn.UNIQUE(tblCarga[Jogador])),ROW()-7)),"")} | C10: =IF(B10="","",IF(D10>=7,"🔴",IF(D10>=4,"🟡","🟢"))) | D10: =IF(B10="","",_xlfn.LET(_xlpm.acwr,G10,_xlpm.monot,H10,_xlpm.dias,I10,_xlpm.tend,F10,_xlpm.cong,T10,_xlpm.hooper,O10,_xlpm.rACWR,IF(_xlpm.acwr="—",0,IF(OR(_xlpm.acwr>1.5,_xlpm.acwr<0.6),3,IF(OR(_xlpm.acwr>1.3,_xlpm.acwr<0.8),2,IF(_xlpm.acwr<=1.1,0.5,0)))),_xlpm.rMonot,IF(_xlpm.monot>2.5,3,IF(_xlpm.monot>2,2,IF(_xlpm.monot>1.5,1,0))),_xlpm.rDias,IF(_xlpm.dias>14,3,IF(_xlpm.dias>7,2,IF(_xlpm.dias>5,1,0))),_xlpm.rTend,IF(AND(_xlpm.tend="↑",_xlpm.acwr>1.1),1,0),_xlpm.rCong,IF(AND(_xlpm.cong<>"—",_xlpm.cong<4),2,IF(AND(_xlpm.cong<>"—",_xlpm.cong<=5),1,0)),_xlpm.rHooper,IF(AND(_xlpm.hooper<>"—",_xlpm.hooper>=15),1,0),MIN(10,ROUND(_xlpm.rACWR+_xlpm.rMonot+_xlpm.rDias+_xlpm.rTend+_xlpm.rCong+_xlpm.rHooper,0)))) | E10: =IF(B10="","",IF(D10<4,"✅ Sem alertas",_xlfn.LET(_xlpm.acwr,G10,_xlpm.monot,H10,_xlpm.dias,I10,_xlpm.reasons,IF(AND(_xlpm.acwr<>"—",OR(_xlpm.acwr>1.3,_xlpm.acwr<0.8)),"ACWR "&ROUND(_xlpm.acwr,2),"")&IF(AND(_xlpm.monot>2,AND(_xlpm.acwr<>"—",OR(_xlpm.acwr>1.3,_xlpm.acwr<0.8)))," | ","")&IF(_xlpm.monot>2,"Monot "&ROUND(_xlpm.monot,1),"")&IF(AND(_xlpm.dias>7,OR(AND(_xlpm.acwr<>"—",OR(_xlpm.acwr>1.3,_xlpm.acwr<0.8)),_xlpm.monot>2))," | ","")&IF(_xlpm.dias>7,"Vmáx "&_xlpm.dias&"d",""),IF(LEN(_xlpm.reasons)>0,_xlpm.reasons,"Múltiplos fatores")))) | F10: {=IF(B10="","",IFERROR(_xlfn.LET(_xlpm.cur,J10,_xlpm.prev,SUMPRODUCT((tblCarga[Jogador]=B10)*(tblCarga[Microciclo (Nr)]=($H$1-1))*(tblCarga[Tipo]="Treino")*tblCarga[PSE Sessão]*tblCarga[Duração (min)]),_xlpm.delta,(_xlpm.cur-_xlpm.prev)/IF(_xlpm.prev=0,1,_xlpm.prev),IF(_xlpm.delta>0.1,"↑",IF(_xlpm.delta<-0.1,"↓","→"))),"—"))} | G10: =IF(B10="","",IFERROR(J10/(P10*0.4+Q10*0.3+R10*0.2+J10*0.1),"—")) | H10: =IF(B10="","",IFERROR(INDEX(Monot_Strain!F$9:F$38,MATCH(B10,Monot_Strain!A$9:A$38,0)),0)) | I10: {=IF(B10="","",IFERROR(TODAY()-MAX(_xlfn._xlws.FILTER(tblCarga[Data],(tblCarga[Jogador]=B10)*(tblCarga[Nº ≥90% Vmáx]>0))),999))} | J10: {=IF(B10="","",SUMPRODUCT((tblCarga[Jogador]=B10)*(tblCarga[Microciclo (Nr)]=$H$1)*(tblCarga[Tipo]="Treino")*tblCarga[PSE Sessão]*tblCarga[Duração (min)]))} | K10: {=IF(B10="","",IFERROR(SUMPRODUCT((tblCarga[Jogador]=B10)*(tblCarga[Microciclo (Nr)]=$H$1)*(tblCarga[Tipo]="Jogo")*tblCarga[Duração (min)]),0))} | L10: {=IF(B10="","",IFERROR(_xlfn.LET(_xlpm.mcs,_xlfn._xlws.SORT(_xlfn.UNIQUE(_xlfn._xlws.FILTER(tblCarga[Microciclo (Nr)],(tblCarga[Jogador]=B10)*(tblCarga[Tipo]="Jogo"))),,,-1),_xlpm.curMC,$H$1,_xlpm.streak,0,IF(ROWS(_xlpm.mcs)=0,0,SUMPRODUCT(--(_xlpm.mcs>=_xlpm.curMC-ROWS(_xlpm.mcs)+1),--(_xlpm.mcs<=_xlpm.curMC)))),0))} | M10: =IF(B10="","",IF(D10>=7,"⚠️ Reduzir carga. Consultar staff médico.",IF(D10>=4,"🔍 Monitorizar. Ajustar volume se necessário.","✅ Manter plano de treino."))) | N10: =IF(B10="","",IF(S10>R10,"▲ "&ROUND(J10,0),IF(S10<R10,"▼ "&ROUND(J10,0),"→ "&ROUND(J10,0)))) | O10: {=IF(B10="","",IFERROR(INDEX(tblCarga[Hooper Index],MATCH(1,(tblCarga[Jogador]=B10)*(tblCarga[Data]=_xlfn.MAXIFS(tblCarga[Data],tblCarga[Jogador],B10,tblCarga[Hooper Index],">0")),0)),"—"))} | P10: {=IF(B10="","",SUMPRODUCT((tblCarga[Jogador]=B10)*(tblCarga[Microciclo (Nr)]=($H$1-3))*(tblCarga[Tipo]="Treino")*tblCarga[PSE Sessão]*tblCarga[Duração (min)]))} | Q10: {=IF(B10="","",SUMPRODUCT((tblCarga[Jogador]=B10)*(tblCarga[Microciclo (Nr)]=($H$1-2))*(tblCarga[Tipo]="Treino")*tblCarga[PSE Sessão]*tblCarga[Duração (min)]))} | R10: {=IF(B10="","",SUMPRODUCT((tblCarga[Jogador]=B10)*(tblCarga[Microciclo (Nr)]=($H$1-1))*(tblCarga[Tipo]="Treino")*tblCarga[PSE Sessão]*tblCarga[Duração (min)]))} | S10: =J10 | T10: =IF(B10="","",IFERROR(TODAY()-_xlfn.MAXIFS(tblCarga[Data],tblCarga[Jogador],B10,tblCarga[Tipo],"Jogo"),"—"))
A11: =IF(B11="","",ROW()-7) | B11: {=IFERROR(IF(INDEX(_xlfn._xlws.SORT(_xlfn.UNIQUE(tblCarga[Jogador])),ROW()-7)=0,"",INDEX(_xlfn._xlws.SORT(_xlfn.UNIQUE(tblCarga[Jogador])),ROW()-7)),"")} | C11: =IF(B11="","",IF(D11>=7,"🔴",IF(D11>=4,"🟡","🟢"))) | D11: =IF(B11="","",_xlfn.LET(_xlpm.acwr,G11,_xlpm.monot,H11,_xlpm.dias,I11,_xlpm.tend,F11,_xlpm.cong,T11,_xlpm.hooper,O11,_xlpm.rACWR,IF(_xlpm.acwr="—",0,IF(OR(_xlpm.acwr>1.5,_xlpm.acwr<0.6),3,IF(OR(_xlpm.acwr>1.3,_xlpm.acwr<0.8),2,IF(_xlpm.acwr<=1.1,0.5,0)))),_xlpm.rMonot,IF(_xlpm.monot>2.5,3,IF(_xlpm.monot>2,2,IF(_xlpm.monot>1.5,1,0))),_xlpm.rDias,IF(_xlpm.dias>14,3,IF(_xlpm.dias>7,2,IF(_xlpm.dias>5,1,0))),_xlpm.rTend,IF(AND(_xlpm.tend="↑",_xlpm.acwr>1.1),1,0),_xlpm.rCong,IF(AND(_xlpm.cong<>"—",_xlpm.cong<4),2,IF(AND(_xlpm.cong<>"—",_xlpm.cong<=5),1,0)),_xlpm.rHooper,IF(AND(_xlpm.hooper<>"—",_xlpm.hooper>=15),1,0),MIN(10,ROUND(_xlpm.rACWR+_xlpm.rMonot+_xlpm.rDias+_xlpm.rTend+_xlpm.rCong+_xlpm.rHooper,0)))) | E11: =IF(B11="","",IF(D11<4,"✅ Sem alertas",_xlfn.LET(_xlpm.acwr,G11,_xlpm.monot,H11,_xlpm.dias,I11,_xlpm.reasons,IF(AND(_xlpm.acwr<>"—",OR(_xlpm.acwr>1.3,_xlpm.acwr<0.8)),"ACWR "&ROUND(_xlpm.acwr,2),"")&IF(AND(_xlpm.monot>2,AND(_xlpm.acwr<>"—",OR(_xlpm.acwr>1.3,_xlpm.acwr<0.8)))," | ","")&IF(_xlpm.monot>2,"Monot "&ROUND(_xlpm.monot,1),"")&IF(AND(_xlpm.dias>7,OR(AND(_xlpm.acwr<>"—",OR(_xlpm.acwr>1.3,_xlpm.acwr<0.8)),_xlpm.monot>2))," | ","")&IF(_xlpm.dias>7,"Vmáx "&_xlpm.dias&"d",""),IF(LEN(_xlpm.reasons)>0,_xlpm.reasons,"Múltiplos fatores")))) | F11: {=IF(B11="","",IFERROR(_xlfn.LET(_xlpm.cur,J11,_xlpm.prev,SUMPRODUCT((tblCarga[Jogador]=B11)*(tblCarga[Microciclo (Nr)]=($H$1-1))*(tblCarga[Tipo]="Treino")*tblCarga[PSE Sessão]*tblCarga[Duração (min)]),_xlpm.delta,(_xlpm.cur-_xlpm.prev)/IF(_xlpm.prev=0,1,_xlpm.prev),IF(_xlpm.delta>0.1,"↑",IF(_xlpm.delta<-0.1,"↓","→"))),"—"))} | G11: =IF(B11="","",IFERROR(J11/AVERAGE(P11,Q11,R11),"—")) | H11: =IF(B11="","",IFERROR(INDEX(Monot_Strain!F$9:F$38,MATCH(B11,Monot_Strain!A$9:A$38,0)),0)) | I11: {=IF(B11="","",IFERROR(TODAY()-MAX(_xlfn._xlws.FILTER(tblCarga[Data],(tblCarga[Jogador]=B11)*(tblCarga[Nº ≥90% Vmáx]>0))),999))} | J11: {=IF(B11="","",SUMPRODUCT((tblCarga[Jogador]=B11)*(tblCarga[Microciclo (Nr)]=$H$1)*(tblCarga[Tipo]="Treino")*tblCarga[PSE Sessão]*tblCarga[Duração (min)]))} | K11: {=IF(B11="","",IFERROR(SUMPRODUCT((tblCarga[Jogador]=B11)*(tblCarga[Microciclo (Nr)]=$H$1)*(tblCarga[Tipo]="Jogo")*tblCarga[Duração (min)]),0))} | L11: {=IF(B11="","",IFERROR(_xlfn.LET(_xlpm.mcs,_xlfn._xlws.SORT(_xlfn.UNIQUE(_xlfn._xlws.FILTER(tblCarga[Microciclo (Nr)],(tblCarga[Jogador]=B11)*(tblCarga[Tipo]="Jogo"))),,,-1),_xlpm.curMC,$H$1,_xlpm.streak,0,IF(ROWS(_xlpm.mcs)=0,0,SUMPRODUCT(--(_xlpm.mcs>=_xlpm.curMC-ROWS(_xlpm.mcs)+1),--(_xlpm.mcs<=_xlpm.curMC)))),0))} | M11: =IF(B11="","",IF(D11>=7,"⚠️ Reduzir carga. Consultar staff médico.",IF(D11>=4,"🔍 Monitorizar. Ajustar volume se necessário.","✅ Manter plano de treino."))) | N11: =IF(B11="","",IF(S11>R11,"▲ "&ROUND(J11,0),IF(S11<R11,"▼ "&ROUND(J11,0),"→ "&ROUND(J11,0)))) | O11: {=IF(B11="","",IFERROR(INDEX(tblCarga[Hooper Index],MATCH(1,(tblCarga[Jogador]=B11)*(tblCarga[Data]=_xlfn.MAXIFS(tblCarga[Data],tblCarga[Jogador],B11,tblCarga[Hooper Index],">0")),0)),"—"))} | P11: {=IF(B11="","",SUMPRODUCT((tblCarga[Jogador]=B11)*(tblCarga[Microciclo (Nr)]=($H$1-3))*(tblCarga[Tipo]="Treino")*tblCarga[PSE Sessão]*tblCarga[Duração (min)]))} | Q11: {=IF(B11="","",SUMPRODUCT((tblCarga[Jogador]=B11)*(tblCarga[Microciclo (Nr)]=($H$1-2))*(tblCarga[Tipo]="Treino")*tblCarga[PSE Sessão]*tblCarga[Duração (min)]))} | R11: {=IF(B11="","",SUMPRODUCT((tblCarga[Jogador]=B11)*(tblCarga[Microciclo (Nr)]=($H$1-1))*(tblCarga[Tipo]="Treino")*tblCarga[PSE Sessão]*tblCarga[Duração (min)]))} | S11: =J11 | T11: =IF(B11="","",IFERROR(TODAY()-_xlfn.MAXIFS(tblCarga[Data],tblCarga[Jogador],B11,tblCarga[Tipo],"Jogo"),"—"))
A12: =IF(B12="","",ROW()-7) | B12: {=IFERROR(IF(INDEX(_xlfn._xlws.SORT(_xlfn.UNIQUE(tblCarga[Jogador])),ROW()-7)=0,"",INDEX(_xlfn._xlws.SORT(_xlfn.UNIQUE(tblCarga[Jogador])),ROW()-7)),"")} | C12: =IF(B12="","",IF(D12>=7,"🔴",IF(D12>=4,"🟡","🟢"))) | D12: =IF(B12="","",_xlfn.LET(_xlpm.acwr,G12,_xlpm.monot,H12,_xlpm.dias,I12,_xlpm.tend,F12,_xlpm.cong,T12,_xlpm.hooper,O12,_xlpm.rACWR,IF(_xlpm.acwr="—",0,IF(OR(_xlpm.acwr>1.5,_xlpm.acwr<0.6),3,IF(OR(_xlpm.acwr>1.3,_xlpm.acwr<0.8),2,IF(_xlpm.acwr<=1.1,0.5,0)))),_xlpm.rMonot,IF(_xlpm.monot>2.5,3,IF(_xlpm.monot>2,2,IF(_xlpm.monot>1.5,1,0))),_xlpm.rDias,IF(_xlpm.dias>14,3,IF(_xlpm.dias>7,2,IF(_xlpm.dias>5,1,0))),_xlpm.rTend,IF(AND(_xlpm.tend="↑",_xlpm.acwr>1.1),1,0),_xlpm.rCong,IF(AND(_xlpm.cong<>"—",_xlpm.cong<4),2,IF(AND(_xlpm.cong<>"—",_xlpm.cong<=5),1,0)),_xlpm.rHooper,IF(AND(_xlpm.hooper<>"—",_xlpm.hooper>=15),1,0),MIN(10,ROUND(_xlpm.rACWR+_xlpm.rMonot+_xlpm.rDias+_xlpm.rTend+_xlpm.rCong+_xlpm.rHooper,0)))) | E12: =IF(B12="","",IF(D12<4,"✅ Sem alertas",_xlfn.LET(_xlpm.acwr,G12,_xlpm.monot,H12,_xlpm.dias,I12,_xlpm.reasons,IF(AND(_xlpm.acwr<>"—",OR(_xlpm.acwr>1.3,_xlpm.acwr<0.8)),"ACWR "&ROUND(_xlpm.acwr,2),"")&IF(AND(_xlpm.monot>2,AND(_xlpm.acwr<>"—",OR(_xlpm.acwr>1.3,_xlpm.acwr<0.8)))," | ","")&IF(_xlpm.monot>2,"Monot "&ROUND(_xlpm.monot,1),"")&IF(AND(_xlpm.dias>7,OR(AND(_xlpm.acwr<>"—",OR(_xlpm.acwr>1.3,_xlpm.acwr<0.8)),_xlpm.monot>2))," | ","")&IF(_xlpm.dias>7,"Vmáx "&_xlpm.dias&"d",""),IF(LEN(_xlpm.reasons)>0,_xlpm.reasons,"Múltiplos fatores")))) | F12: {=IF(B12="","",IFERROR(_xlfn.LET(_xlpm.cur,J12,_xlpm.prev,SUMPRODUCT((tblCarga[Jogador]=B12)*(tblCarga[Microciclo (Nr)]=($H$1-1))*(tblCarga[Tipo]="Treino")*tblCarga[PSE Sessão]*tblCarga[Duração (min)]),_xlpm.delta,(_xlpm.cur-_xlpm.prev)/IF(_xlpm.prev=0,1,_xlpm.prev),IF(_xlpm.delta>0.1,"↑",IF(_xlpm.delta<-0.1,"↓","→"))),"—"))} | G12: =IF(B12="","",IFERROR(J12/AVERAGE(P12,Q12,R12),"—")) | H12: =IF(B12="","",IFERROR(INDEX(Monot_Strain!F$9:F$38,MATCH(B12,Monot_Strain!A$9:A$38,0)),0)) | I12: {=IF(B12="","",IFERROR(TODAY()-MAX(_xlfn._xlws.FILTER(tblCarga[Data],(tblCarga[Jogador]=B12)*(tblCarga[Nº ≥90% Vmáx]>0))),999))} | J12: {=IF(B12="","",SUMPRODUCT((tblCarga[Jogador]=B12)*(tblCarga[Microciclo (Nr)]=$H$1)*(tblCarga[Tipo]="Treino")*tblCarga[PSE Sessão]*tblCarga[Duração (min)]))} | K12: {=IF(B12="","",IFERROR(SUMPRODUCT((tblCarga[Jogador]=B12)*(tblCarga[Microciclo (Nr)]=$H$1)*(tblCarga[Tipo]="Jogo")*tblCarga[Duração (min)]),0))} | L12: {=IF(B12="","",IFERROR(_xlfn.LET(_xlpm.mcs,_xlfn._xlws.SORT(_xlfn.UNIQUE(_xlfn._xlws.FILTER(tblCarga[Microciclo (Nr)],(tblCarga[Jogador]=B12)*(tblCarga[Tipo]="Jogo"))),,,-1),_xlpm.curMC,$H$1,_xlpm.streak,0,IF(ROWS(_xlpm.mcs)=0,0,SUMPRODUCT(--(_xlpm.mcs>=_xlpm.curMC-ROWS(_xlpm.mcs)+1),--(_xlpm.mcs<=_xlpm.curMC)))),0))} | M12: =IF(B12="","",IF(D12>=7,"⚠️ Reduzir carga. Consultar staff médico.",IF(D12>=4,"🔍 Monitorizar. Ajustar volume se necessário.","✅ Manter plano de treino."))) | N12: =IF(B12="","",IF(S12>R12,"▲ "&ROUND(J12,0),IF(S12<R12,"▼ "&ROUND(J12,0),"→ "&ROUND(J12,0)))) | O12: {=IF(B12="","",IFERROR(INDEX(tblCarga[Hooper Index],MATCH(1,(tblCarga[Jogador]=B12)*(tblCarga[Data]=_xlfn.MAXIFS(tblCarga[Data],tblCarga[Jogador],B12,tblCarga[Hooper Index],">0")),0)),"—"))} | P12: {=IF(B12="","",SUMPRODUCT((tblCarga[Jogador]=B12)*(tblCarga[Microciclo (Nr)]=($H$1-3))*(tblCarga[Tipo]="Treino")*tblCarga[PSE Sessão]*tblCarga[Duração (min)]))} | Q12: {=IF(B12="","",SUMPRODUCT((tblCarga[Jogador]=B12)*(tblCarga[Microciclo (Nr)]=($H$1-2))*(tblCarga[Tipo]="Treino")*tblCarga[PSE Sessão]*tblCarga[Duração (min)]))} | R12: {=IF(B12="","",SUMPRODUCT((tblCarga[Jogador]=B12)*(tblCarga[Microciclo (Nr)]=($H$1-1))*(tblCarga[Tipo]="Treino")*tblCarga[PSE Sessão]*tblCarga[Duração (min)]))} | S12: =J12 | T12: =IF(B12="","",IFERROR(TODAY()-_xlfn.MAXIFS(tblCarga[Data],tblCarga[Jogador],B12,tblCarga[Tipo],"Jogo"),"—"))
A13: =IF(B13="","",ROW()-7) | B13: {=IFERROR(IF(INDEX(_xlfn._xlws.SORT(_xlfn.UNIQUE(tblCarga[Jogador])),ROW()-7)=0,"",INDEX(_xlfn._xlws.SORT(_xlfn.UNIQUE(tblCarga[Jogador])),ROW()-7)),"")} | C13: =IF(B13="","",IF(D13>=7,"🔴",IF(D13>=4,"🟡","🟢"))) | D13: =IF(B13="","",_xlfn.LET(_xlpm.acwr,G13,_xlpm.monot,H13,_xlpm.dias,I13,_xlpm.tend,F13,_xlpm.cong,T13,_xlpm.hooper,O13,_xlpm.rACWR,IF(_xlpm.acwr="—",0,IF(OR(_xlpm.acwr>1.5,_xlpm.acwr<0.6),3,IF(OR(_xlpm.acwr>1.3,_xlpm.acwr<0.8),2,IF(_xlpm.acwr<=1.1,0.5,0)))),_xlpm.rMonot,IF(_xlpm.monot>2.5,3,IF(_xlpm.monot>2,2,IF(_xlpm.monot>1.5,1,0))),_xlpm.rDias,IF(_xlpm.dias>14,3,IF(_xlpm.dias>7,2,IF(_xlpm.dias>5,1,0))),_xlpm.rTend,IF(AND(_xlpm.tend="↑",_xlpm.acwr>1.1),1,0),_xlpm.rCong,IF(AND(_xlpm.cong<>"—",_xlpm.cong<4),2,IF(AND(_xlpm.cong<>"—",_xlpm.cong<=5),1,0)),_xlpm.rHooper,IF(AND(_xlpm.hooper<>"—",_xlpm.hooper>=15),1,0),MIN(10,ROUND(_xlpm.rACWR+_xlpm.rMonot+_xlpm.rDias+_xlpm.rTend+_xlpm.rCong+_xlpm.rHooper,0)))) | E13: =IF(B13="","",IF(D13<4,"✅ Sem alertas",_xlfn.LET(_xlpm.acwr,G13,_xlpm.monot,H13,_xlpm.dias,I13,_xlpm.reasons,IF(AND(_xlpm.acwr<>"—",OR(_xlpm.acwr>1.3,_xlpm.acwr<0.8)),"ACWR "&ROUND(_xlpm.acwr,2),"")&IF(AND(_xlpm.monot>2,AND(_xlpm.acwr<>"—",OR(_xlpm.acwr>1.3,_xlpm.acwr<0.8)))," | ","")&IF(_xlpm.monot>2,"Monot "&ROUND(_xlpm.monot,1),"")&IF(AND(_xlpm.dias>7,OR(AND(_xlpm.acwr<>"—",OR(_xlpm.acwr>1.3,_xlpm.acwr<0.8)),_xlpm.monot>2))," | ","")&IF(_xlpm.dias>7,"Vmáx "&_xlpm.dias&"d",""),IF(LEN(_xlpm.reasons)>0,_xlpm.reasons,"Múltiplos fatores")))) | F13: {=IF(B13="","",IFERROR(_xlfn.LET(_xlpm.cur,J13,_xlpm.prev,SUMPRODUCT((tblCarga[Jogador]=B13)*(tblCarga[Microciclo (Nr)]=($H$1-1))*(tblCarga[Tipo]="Treino")*tblCarga[PSE Sessão]*tblCarga[Duração (min)]),_xlpm.delta,(_xlpm.cur-_xlpm.prev)/IF(_xlpm.prev=0,1,_xlpm.prev),IF(_xlpm.delta>0.1,"↑",IF(_xlpm.delta<-0.1,"↓","→"))),"—"))} | G13: =IF(B13="","",IFERROR(J13/AVERAGE(P13,Q13,R13),"—")) | H13: =IF(B13="","",IFERROR(INDEX(Monot_Strain!F$9:F$38,MATCH(B13,Monot_Strain!A$9:A$38,0)),0)) | I13: {=IF(B13="","",IFERROR(TODAY()-MAX(_xlfn._xlws.FILTER(tblCarga[Data],(tblCarga[Jogador]=B13)*(tblCarga[Nº ≥90% Vmáx]>0))),999))} | J13: {=IF(B13="","",SUMPRODUCT((tblCarga[Jogador]=B13)*(tblCarga[Microciclo (Nr)]=$H$1)*(tblCarga[Tipo]="Treino")*tblCarga[PSE Sessão]*tblCarga[Duração (min)]))} | K13: {=IF(B13="","",IFERROR(SUMPRODUCT((tblCarga[Jogador]=B13)*(tblCarga[Microciclo (Nr)]=$H$1)*(tblCarga[Tipo]="Jogo")*tblCarga[Duração (min)]),0))} | L13: {=IF(B13="","",IFERROR(_xlfn.LET(_xlpm.mcs,_xlfn._xlws.SORT(_xlfn.UNIQUE(_xlfn._xlws.FILTER(tblCarga[Microciclo (Nr)],(tblCarga[Jogador]=B13)*(tblCarga[Tipo]="Jogo"))),,,-1),_xlpm.curMC,$H$1,_xlpm.streak,0,IF(ROWS(_xlpm.mcs)=0,0,SUMPRODUCT(--(_xlpm.mcs>=_xlpm.curMC-ROWS(_xlpm.mcs)+1),--(_xlpm.mcs<=_xlpm.curMC)))),0))} | M13: =IF(B13="","",IF(D13>=7,"⚠️ Reduzir carga. Consultar staff médico.",IF(D13>=4,"🔍 Monitorizar. Ajustar volume se necessário.","✅ Manter plano de treino."))) | N13: =IF(B13="","",IF(S13>R13,"▲ "&ROUND(J13,0),IF(S13<R13,"▼ "&ROUND(J13,0),"→ "&ROUND(J13,0)))) | O13: {=IF(B13="","",IFERROR(INDEX(tblCarga[Hooper Index],MATCH(1,(tblCarga[Jogador]=B13)*(tblCarga[Data]=_xlfn.MAXIFS(tblCarga[Data],tblCarga[Jogador],B13,tblCarga[Hooper Index],">0")),0)),"—"))} | P13: {=IF(B13="","",SUMPRODUCT((tblCarga[Jogador]=B13)*(tblCarga[Microciclo (Nr)]=($H$1-3))*(tblCarga[Tipo]="Treino")*tblCarga[PSE Sessão]*tblCarga[Duração (min)]))} | Q13: {=IF(B13="","",SUMPRODUCT((tblCarga[Jogador]=B13)*(tblCarga[Microciclo (Nr)]=($H$1-2))*(tblCarga[Tipo]="Treino")*tblCarga[PSE Sessão]*tblCarga[Duração (min)]))} | R13: {=IF(B13="","",SUMPRODUCT((tblCarga[Jogador]=B13)*(tblCarga[Microciclo (Nr)]=($H$1-1))*(tblCarga[Tipo]="Treino")*tblCarga[PSE Sessão]*tblCarga[Duração (min)]))} | S13: =J13 | T13: =IF(B13="","",IFERROR(TODAY()-_xlfn.MAXIFS(tblCarga[Data],tblCarga[Jogador],B13,tblCarga[Tipo],"Jogo"),"—"))
A14: =IF(B14="","",ROW()-7) | B14: {=IFERROR(IF(INDEX(_xlfn._xlws.SORT(_xlfn.UNIQUE(tblCarga[Jogador])),ROW()-7)=0,"",INDEX(_xlfn._xlws.SORT(_xlfn.UNIQUE(tblCarga[Jogador])),ROW()-7)),"")} | C14: =IF(B14="","",IF(D14>=7,"🔴",IF(D14>=4,"🟡","🟢"))) | D14: =IF(B14="","",_xlfn.LET(_xlpm.acwr,G14,_xlpm.monot,H14,_xlpm.dias,I14,_xlpm.tend,F14,_xlpm.cong,T14,_xlpm.hooper,O14,_xlpm.rACWR,IF(_xlpm.acwr="—",0,IF(OR(_xlpm.acwr>1.5,_xlpm.acwr<0.6),3,IF(OR(_xlpm.acwr>1.3,_xlpm.acwr<0.8),2,IF(_xlpm.acwr<=1.1,0.5,0)))),_xlpm.rMonot,IF(_xlpm.monot>2.5,3,IF(_xlpm.monot>2,2,IF(_xlpm.monot>1.5,1,0))),_xlpm.rDias,IF(_xlpm.dias>14,3,IF(_xlpm.dias>7,2,IF(_xlpm.dias>5,1,0))),_xlpm.rTend,IF(AND(_xlpm.tend="↑",_xlpm.acwr>1.1),1,0),_xlpm.rCong,IF(AND(_xlpm.cong<>"—",_xlpm.cong<4),2,IF(AND(_xlpm.cong<>"—",_xlpm.cong<=5),1,0)),_xlpm.rHooper,IF(AND(_xlpm.hooper<>"—",_xlpm.hooper>=15),1,0),MIN(10,ROUND(_xlpm.rACWR+_xlpm.rMonot+_xlpm.rDias+_xlpm.rTend+_xlpm.rCong+_xlpm.rHooper,0)))) | E14: =IF(B14="","",IF(D14<4,"✅ Sem alertas",_xlfn.LET(_xlpm.acwr,G14,_xlpm.monot,H14,_xlpm.dias,I14,_xlpm.reasons,IF(AND(_xlpm.acwr<>"—",OR(_xlpm.acwr>1.3,_xlpm.acwr<0.8)),"ACWR "&ROUND(_xlpm.acwr,2),"")&IF(AND(_xlpm.monot>2,AND(_xlpm.acwr<>"—",OR(_xlpm.acwr>1.3,_xlpm.acwr<0.8)))," | ","")&IF(_xlpm.monot>2,"Monot "&ROUND(_xlpm.monot,1),"")&IF(AND(_xlpm.dias>7,OR(AND(_xlpm.acwr<>"—",OR(_xlpm.acwr>1.3,_xlpm.acwr<0.8)),_xlpm.monot>2))," | ","")&IF(_xlpm.dias>7,"Vmáx "&_xlpm.dias&"d",""),IF(LEN(_xlpm.reasons)>0,_xlpm.reasons,"Múltiplos fatores")))) | F14: {=IF(B14="","",IFERROR(_xlfn.LET(_xlpm.cur,J14,_xlpm.prev,SUMPRODUCT((tblCarga[Jogador]=B14)*(tblCarga[Microciclo (Nr)]=($H$1-1))*(tblCarga[Tipo]="Treino")*tblCarga[PSE Sessão]*tblCarga[Duração (min)]),_xlpm.delta,(_xlpm.cur-_xlpm.prev)/IF(_xlpm.prev=0,1,_xlpm.prev),IF(_xlpm.delta>0.1,"↑",IF(_xlpm.delta<-0.1,"↓","→"))),"—"))} | G14: =IF(B14="","",IFERROR(J14/AVERAGE(P14,Q14,R14),"—")) | H14: =IF(B14="","",IFERROR(INDEX(Monot_Strain!F$9:F$38,MATCH(B14,Monot_Strain!A$9:A$38,0)),0)) | I14: {=IF(B14="","",IFERROR(TODAY()-MAX(_xlfn._xlws.FILTER(tblCarga[Data],(tblCarga[Jogador]=B14)*(tblCarga[Nº ≥90% Vmáx]>0))),999))} | J14: {=IF(B14="","",SUMPRODUCT((tblCarga[Jogador]=B14)*(tblCarga[Microciclo (Nr)]=$H$1)*(tblCarga[Tipo]="Treino")*tblCarga[PSE Sessão]*tblCarga[Duração (min)]))} | K14: {=IF(B14="","",IFERROR(SUMPRODUCT((tblCarga[Jogador]=B14)*(tblCarga[Microciclo (Nr)]=$H$1)*(tblCarga[Tipo]="Jogo")*tblCarga[Duração (min)]),0))} | L14: {=IF(B14="","",IFERROR(_xlfn.LET(_xlpm.mcs,_xlfn._xlws.SORT(_xlfn.UNIQUE(_xlfn._xlws.FILTER(tblCarga[Microciclo (Nr)],(tblCarga[Jogador]=B14)*(tblCarga[Tipo]="Jogo"))),,,-1),_xlpm.curMC,$H$1,_xlpm.streak,0,IF(ROWS(_xlpm.mcs)=0,0,SUMPRODUCT(--(_xlpm.mcs>=_xlpm.curMC-ROWS(_xlpm.mcs)+1),--(_xlpm.mcs<=_xlpm.curMC)))),0))} | M14: =IF(B14="","",IF(D14>=7,"⚠️ Reduzir carga. Consultar staff médico.",IF(D14>=4,"🔍 Monitorizar. Ajustar volume se necessário.","✅ Manter plano de treino."))) | N14: =IF(B14="","",IF(S14>R14,"▲ "&ROUND(J14,0),IF(S14<R14,"▼ "&ROUND(J14,0),"→ "&ROUND(J14,0)))) | O14: {=IF(B14="","",IFERROR(INDEX(tblCarga[Hooper Index],MATCH(1,(tblCarga[Jogador]=B14)*(tblCarga[Data]=_xlfn.MAXIFS(tblCarga[Data],tblCarga[Jogador],B14,tblCarga[Hooper Index],">0")),0)),"—"))} | P14: {=IF(B14="","",SUMPRODUCT((tblCarga[Jogador]=B14)*(tblCarga[Microciclo (Nr)]=($H$1-3))*(tblCarga[Tipo]="Treino")*tblCarga[PSE Sessão]*tblCarga[Duração (min)]))} | Q14: {=IF(B14="","",SUMPRODUCT((tblCarga[Jogador]=B14)*(tblCarga[Microciclo (Nr)]=($H$1-2))*(tblCarga[Tipo]="Treino")*tblCarga[PSE Sessão]*tblCarga[Duração (min)]))} | R14: {=IF(B14="","",SUMPRODUCT((tblCarga[Jogador]=B14)*(tblCarga[Microciclo (Nr)]=($H$1-1))*(tblCarga[Tipo]="Treino")*tblCarga[PSE Sessão]*tblCarga[Duração (min)]))} | S14: =J14 | T14: =IF(B14="","",IFERROR(TODAY()-_xlfn.MAXIFS(tblCarga[Data],tblCarga[Jogador],B14,tblCarga[Tipo],"Jogo"),"—"))
A15: =IF(B15="","",ROW()-7) | B15: {=IFERROR(IF(INDEX(_xlfn._xlws.SORT(_xlfn.UNIQUE(tblCarga[Jogador])),ROW()-7)=0,"",INDEX(_xlfn._xlws.SORT(_xlfn.UNIQUE(tblCarga[Jogador])),ROW()-7)),"")} | C15: =IF(B15="","",IF(D15>=7,"🔴",IF(D15>=4,"🟡","🟢"))) | D15: =IF(B15="","",_xlfn.LET(_xlpm.acwr,G15,_xlpm.monot,H15,_xlpm.dias,I15,_xlpm.tend,F15,_xlpm.cong,T15,_xlpm.hooper,O15,_xlpm.rACWR,IF(_xlpm.acwr="—",0,IF(OR(_xlpm.acwr>1.5,_xlpm.acwr<0.6),3,IF(OR(_xlpm.acwr>1.3,_xlpm.acwr<0.8),2,IF(_xlpm.acwr<=1.1,0.5,0)))),_xlpm.rMonot,IF(_xlpm.monot>2.5,3,IF(_xlpm.monot>2,2,IF(_xlpm.monot>1.5,1,0))),_xlpm.rDias,IF(_xlpm.dias>14,3,IF(_xlpm.dias>7,2,IF(_xlpm.dias>5,1,0))),_xlpm.rTend,IF(AND(_xlpm.tend="↑",_xlpm.acwr>1.1),1,0),_xlpm.rCong,IF(AND(_xlpm.cong<>"—",_xlpm.cong<4),2,IF(AND(_xlpm.cong<>"—",_xlpm.cong<=5),1,0)),_xlpm.rHooper,IF(AND(_xlpm.hooper<>"—",_xlpm.hooper>=15),1,0),MIN(10,ROUND(_xlpm.rACWR+_xlpm.rMonot+_xlpm.rDias+_xlpm.rTend+_xlpm.rCong+_xlpm.rHooper,0)))) | E15: =IF(B15="","",IF(D15<4,"✅ Sem alertas",_xlfn.LET(_xlpm.acwr,G15,_xlpm.monot,H15,_xlpm.dias,I15,_xlpm.reasons,IF(AND(_xlpm.acwr<>"—",OR(_xlpm.acwr>1.3,_xlpm.acwr<0.8)),"ACWR "&ROUND(_xlpm.acwr,2),"")&IF(AND(_xlpm.monot>2,AND(_xlpm.acwr<>"—",OR(_xlpm.acwr>1.3,_xlpm.acwr<0.8)))," | ","")&IF(_xlpm.monot>2,"Monot "&ROUND(_xlpm.monot,1),"")&IF(AND(_xlpm.dias>7,OR(AND(_xlpm.acwr<>"—",OR(_xlpm.acwr>1.3,_xlpm.acwr<0.8)),_xlpm.monot>2))," | ","")&IF(_xlpm.dias>7,"Vmáx "&_xlpm.dias&"d",""),IF(LEN(_xlpm.reasons)>0,_xlpm.reasons,"Múltiplos fatores")))) | F15: {=IF(B15="","",IFERROR(_xlfn.LET(_xlpm.cur,J15,_xlpm.prev,SUMPRODUCT((tblCarga[Jogador]=B15)*(tblCarga[Microciclo (Nr)]=($H$1-1))*(tblCarga[Tipo]="Treino")*tblCarga[PSE Sessão]*tblCarga[Duração (min)]),_xlpm.delta,(_xlpm.cur-_xlpm.prev)/IF(_xlpm.prev=0,1,_xlpm.prev),IF(_xlpm.delta>0.1,"↑",IF(_xlpm.delta<-0.1,"↓","→"))),"—"))} | G15: =IF(B15="","",IFERROR(J15/AVERAGE(P15,Q15,R15),"—")) | H15: =IF(B15="","",IFERROR(INDEX(Monot_Strain!F$9:F$38,MATCH(B15,Monot_Strain!A$9:A$38,0)),0)) | I15: {=IF(B15="","",IFERROR(TODAY()-MAX(_xlfn._xlws.FILTER(tblCarga[Data],(tblCarga[Jogador]=B15)*(tblCarga[Nº ≥90% Vmáx]>0))),999))} | J15: {=IF(B15="","",SUMPRODUCT((tblCarga[Jogador]=B15)*(tblCarga[Microciclo (Nr)]=$H$1)*(tblCarga[Tipo]="Treino")*tblCarga[PSE Sessão]*tblCarga[Duração (min)]))} | K15: {=IF(B15="","",IFERROR(SUMPRODUCT((tblCarga[Jogador]=B15)*(tblCarga[Microciclo (Nr)]=$H$1)*(tblCarga[Tipo]="Jogo")*tblCarga[Duração (min)]),0))} | L15: {=IF(B15="","",IFERROR(_xlfn.LET(_xlpm.mcs,_xlfn._xlws.SORT(_xlfn.UNIQUE(_xlfn._xlws.FILTER(tblCarga[Microciclo (Nr)],(tblCarga[Jogador]=B15)*(tblCarga[Tipo]="Jogo"))),,,-1),_xlpm.curMC,$H$1,_xlpm.streak,0,IF(ROWS(_xlpm.mcs)=0,0,SUMPRODUCT(--(_xlpm.mcs>=_xlpm.curMC-ROWS(_xlpm.mcs)+1),--(_xlpm.mcs<=_xlpm.curMC)))),0))} | M15: =IF(B15="","",IF(D15>=7,"⚠️ Reduzir carga. Consultar staff médico.",IF(D15>=4,"🔍 Monitorizar. Ajustar volume se necessário.","✅ Manter plano de treino."))) | N15: =IF(B15="","",IF(S15>R15,"▲ "&ROUND(J15,0),IF(S15<R15,"▼ "&ROUND(J15,0),"→ "&ROUND(J15,0)))) | O15: {=IF(B15="","",IFERROR(INDEX(tblCarga[Hooper Index],MATCH(1,(tblCarga[Jogador]=B15)*(tblCarga[Data]=_xlfn.MAXIFS(tblCarga[Data],tblCarga[Jogador],B15,tblCarga[Hooper Index],">0")),0)),"—"))} | P15: {=IF(B15="","",SUMPRODUCT((tblCarga[Jogador]=B15)*(tblCarga[Microciclo (Nr)]=($H$1-3))*(tblCarga[Tipo]="Treino")*tblCarga[PSE Sessão]*tblCarga[Duração (min)]))} | Q15: {=IF(B15="","",SUMPRODUCT((tblCarga[Jogador]=B15)*(tblCarga[Microciclo (Nr)]=($H$1-2))*(tblCarga[Tipo]="Treino")*tblCarga[PSE Sessão]*tblCarga[Duração (min)]))} | R15: {=IF(B15="","",SUMPRODUCT((tblCarga[Jogador]=B15)*(tblCarga[Microciclo (Nr)]=($H$1-1))*(tblCarga[Tipo]="Treino")*tblCarga[PSE Sessão]*tblCarga[Duração (min)]))} | S15: =J15 | T15: =IF(B15="","",IFERROR(TODAY()-_xlfn.MAXIFS(tblCarga[Data],tblCarga[Jogador],B15,tblCarga[Tipo],"Jogo"),"—"))
A16: =IF(B16="","",ROW()-7) | B16: {=IFERROR(IF(INDEX(_xlfn._xlws.SORT(_xlfn.UNIQUE(tblCarga[Jogador])),ROW()-7)=0,"",INDEX(_xlfn._xlws.SORT(_xlfn.UNIQUE(tblCarga[Jogador])),ROW()-7)),"")} | C16: =IF(B16="","",IF(D16>=7,"🔴",IF(D16>=4,"🟡","🟢"))) | D16: =IF(B16="","",_xlfn.LET(_xlpm.acwr,G16,_xlpm.monot,H16,_xlpm.dias,I16,_xlpm.tend,F16,_xlpm.cong,T16,_xlpm.hooper,O16,_xlpm.rACWR,IF(_xlpm.acwr="—",0,IF(OR(_xlpm.acwr>1.5,_xlpm.acwr<0.6),3,IF(OR(_xlpm.acwr>1.3,_xlpm.acwr<0.8),2,IF(_xlpm.acwr<=1.1,0.5,0)))),_xlpm.rMonot,IF(_xlpm.monot>2.5,3,IF(_xlpm.monot>2,2,IF(_xlpm.monot>1.5,1,0))),_xlpm.rDias,IF(_xlpm.dias>14,3,IF(_xlpm.dias>7,2,IF(_xlpm.dias>5,1,0))),_xlpm.rTend,IF(AND(_xlpm.tend="↑",_xlpm.acwr>1.1),1,0),_xlpm.rCong,IF(AND(_xlpm.cong<>"—",_xlpm.cong<4),2,IF(AND(_xlpm.cong<>"—",_xlpm.cong<=5),1,0)),_xlpm.rHooper,IF(AND(_xlpm.hooper<>"—",_xlpm.hooper>=15),1,0),MIN(10,ROUND(_xlpm.rACWR+_xlpm.rMonot+_xlpm.rDias+_xlpm.rTend+_xlpm.rCong+_xlpm.rHooper,0)))) | E16: =IF(B16="","",IF(D16<4,"✅ Sem alertas",_xlfn.LET(_xlpm.acwr,G16,_xlpm.monot,H16,_xlpm.dias,I16,_xlpm.reasons,IF(AND(_xlpm.acwr<>"—",OR(_xlpm.acwr>1.3,_xlpm.acwr<0.8)),"ACWR "&ROUND(_xlpm.acwr,2),"")&IF(AND(_xlpm.monot>2,AND(_xlpm.acwr<>"—",OR(_xlpm.acwr>1.3,_xlpm.acwr<0.8)))," | ","")&IF(_xlpm.monot>2,"Monot "&ROUND(_xlpm.monot,1),"")&IF(AND(_xlpm.dias>7,OR(AND(_xlpm.acwr<>"—",OR(_xlpm.acwr>1.3,_xlpm.acwr<0.8)),_xlpm.monot>2))," | ","")&IF(_xlpm.dias>7,"Vmáx "&_xlpm.dias&"d",""),IF(LEN(_xlpm.reasons)>0,_xlpm.reasons,"Múltiplos fatores")))) | F16: {=IF(B16="","",IFERROR(_xlfn.LET(_xlpm.cur,J16,_xlpm.prev,SUMPRODUCT((tblCarga[Jogador]=B16)*(tblCarga[Microciclo (Nr)]=($H$1-1))*(tblCarga[Tipo]="Treino")*tblCarga[PSE Sessão]*tblCarga[Duração (min)]),_xlpm.delta,(_xlpm.cur-_xlpm.prev)/IF(_xlpm.prev=0,1,_xlpm.prev),IF(_xlpm.delta>0.1,"↑",IF(_xlpm.delta<-0.1,"↓","→"))),"—"))} | G16: =IF(B16="","",IFERROR(J16/AVERAGE(P16,Q16,R16),"—")) | H16: =IF(B16="","",IFERROR(INDEX(Monot_Strain!F$9:F$38,MATCH(B16,Monot_Strain!A$9:A$38,0)),0)) | I16: {=IF(B16="","",IFERROR(TODAY()-MAX(_xlfn._xlws.FILTER(tblCarga[Data],(tblCarga[Jogador]=B16)*(tblCarga[Nº ≥90% Vmáx]>0))),999))} | J16: {=IF(B16="","",SUMPRODUCT((tblCarga[Jogador]=B16)*(tblCarga[Microciclo (Nr)]=$H$1)*(tblCarga[Tipo]="Treino")*tblCarga[PSE Sessão]*tblCarga[Duração (min)]))} | K16: {=IF(B16="","",IFERROR(SUMPRODUCT((tblCarga[Jogador]=B16)*(tblCarga[Microciclo (Nr)]=$H$1)*(tblCarga[Tipo]="Jogo")*tblCarga[Duração (min)]),0))} | L16: {=IF(B16="","",IFERROR(_xlfn.LET(_xlpm.mcs,_xlfn._xlws.SORT(_xlfn.UNIQUE(_xlfn._xlws.FILTER(tblCarga[Microciclo (Nr)],(tblCarga[Jogador]=B16)*(tblCarga[Tipo]="Jogo"))),,,-1),_xlpm.curMC,$H$1,_xlpm.streak,0,IF(ROWS(_xlpm.mcs)=0,0,SUMPRODUCT(--(_xlpm.mcs>=_xlpm.curMC-ROWS(_xlpm.mcs)+1),--(_xlpm.mcs<=_xlpm.curMC)))),0))} | M16: =IF(B16="","",IF(D16>=7,"⚠️ Reduzir carga. Consultar staff médico.",IF(D16>=4,"🔍 Monitorizar. Ajustar volume se necessário.","✅ Manter plano de treino."))) | N16: =IF(B16="","",IF(S16>R16,"▲ "&ROUND(J16,0),IF(S16<R16,"▼ "&ROUND(J16,0),"→ "&ROUND(J16,0)))) | O16: {=IF(B16="","",IFERROR(INDEX(tblCarga[Hooper Index],MATCH(1,(tblCarga[Jogador]=B16)*(tblCarga[Data]=_xlfn.MAXIFS(tblCarga[Data],tblCarga[Jogador],B16,tblCarga[Hooper Index],">0")),0)),"—"))} | P16: {=IF(B16="","",SUMPRODUCT((tblCarga[Jogador]=B16)*(tblCarga[Microciclo (Nr)]=($H$1-3))*(tblCarga[Tipo]="Treino")*tblCarga[PSE Sessão]*tblCarga[Duração (min)]))} | Q16: {=IF(B16="","",SUMPRODUCT((tblCarga[Jogador]=B16)*(tblCarga[Microciclo (Nr)]=($H$1-2))*(tblCarga[Tipo]="Treino")*tblCarga[PSE Sessão]*tblCarga[Duração (min)]))} | R16: {=IF(B16="","",SUMPRODUCT((tblCarga[Jogador]=B16)*(tblCarga[Microciclo (Nr)]=($H$1-1))*(tblCarga[Tipo]="Treino")*tblCarga[PSE Sessão]*tblCarga[Duração (min)]))} | S16: =J16 | T16: =IF(B16="","",IFERROR(TODAY()-_xlfn.MAXIFS(tblCarga[Data],tblCarga[Jogador],B16,tblCarga[Tipo],"Jogo"),"—"))
A17: =IF(B17="","",ROW()-7) | B17: {=IFERROR(IF(INDEX(_xlfn._xlws.SORT(_xlfn.UNIQUE(tblCarga[Jogador])),ROW()-7)=0,"",INDEX(_xlfn._xlws.SORT(_xlfn.UNIQUE(tblCarga[Jogador])),ROW()-7)),"")} | C17: =IF(B17="","",IF(D17>=7,"🔴",IF(D17>=4,"🟡","🟢"))) | D17: =IF(B17="","",_xlfn.LET(_xlpm.acwr,G17,_xlpm.monot,H17,_xlpm.dias,I17,_xlpm.tend,F17,_xlpm.cong,T17,_xlpm.hooper,O17,_xlpm.rACWR,IF(_xlpm.acwr="—",0,IF(OR(_xlpm.acwr>1.5,_xlpm.acwr<0.6),3,IF(OR(_xlpm.acwr>1.3,_xlpm.acwr<0.8),2,IF(_xlpm.acwr<=1.1,0.5,0)))),_xlpm.rMonot,IF(_xlpm.monot>2.5,3,IF(_xlpm.monot>2,2,IF(_xlpm.monot>1.5,1,0))),_xlpm.rDias,IF(_xlpm.dias>14,3,IF(_xlpm.dias>7,2,IF(_xlpm.dias>5,1,0))),_xlpm.rTend,IF(AND(_xlpm.tend="↑",_xlpm.acwr>1.1),1,0),_xlpm.rCong,IF(AND(_xlpm.cong<>"—",_xlpm.cong<4),2,IF(AND(_xlpm.cong<>"—",_xlpm.cong<=5),1,0)),_xlpm.rHooper,IF(AND(_xlpm.hooper<>"—",_xlpm.hooper>=15),1,0),MIN(10,ROUND(_xlpm.rACWR+_xlpm.rMonot+_xlpm.rDias+_xlpm.rTend+_xlpm.rCong+_xlpm.rHooper,0)))) | E17: =IF(B17="","",IF(D17<4,"✅ Sem alertas",_xlfn.LET(_xlpm.acwr,G17,_xlpm.monot,H17,_xlpm.dias,I17,_xlpm.reasons,IF(AND(_xlpm.acwr<>"—",OR(_xlpm.acwr>1.3,_xlpm.acwr<0.8)),"ACWR "&ROUND(_xlpm.acwr,2),"")&IF(AND(_xlpm.monot>2,AND(_xlpm.acwr<>"—",OR(_xlpm.acwr>1.3,_xlpm.acwr<0.8)))," | ","")&IF(_xlpm.monot>2,"Monot "&ROUND(_xlpm.monot,1),"")&IF(AND(_xlpm.dias>7,OR(AND(_xlpm.acwr<>"—",OR(_xlpm.acwr>1.3,_xlpm.acwr<0.8)),_xlpm.monot>2))," | ","")&IF(_xlpm.dias>7,"Vmáx "&_xlpm.dias&"d",""),IF(LEN(_xlpm.reasons)>0,_xlpm.reasons,"Múltiplos fatores")))) | F17: {=IF(B17="","",IFERROR(_xlfn.LET(_xlpm.cur,J17,_xlpm.prev,SUMPRODUCT((tblCarga[Jogador]=B17)*(tblCarga[Microciclo (Nr)]=($H$1-1))*(tblCarga[Tipo]="Treino")*tblCarga[PSE Sessão]*tblCarga[Duração (min)]),_xlpm.delta,(_xlpm.cur-_xlpm.prev)/IF(_xlpm.prev=0,1,_xlpm.prev),IF(_xlpm.delta>0.1,"↑",IF(_xlpm.delta<-0.1,"↓","→"))),"—"))} | G17: =IF(B17="","",IFERROR(J17/AVERAGE(P17,Q17,R17),"—")) | H17: =IF(B17="","",IFERROR(INDEX(Monot_Strain!F$9:F$38,MATCH(B17,Monot_Strain!A$9:A$38,0)),0)) | I17: {=IF(B17="","",IFERROR(TODAY()-MAX(_xlfn._xlws.FILTER(tblCarga[Data],(tblCarga[Jogador]=B17)*(tblCarga[Nº ≥90% Vmáx]>0))),999))} | J17: {=IF(B17="","",SUMPRODUCT((tblCarga[Jogador]=B17)*(tblCarga[Microciclo (Nr)]=$H$1)*(tblCarga[Tipo]="Treino")*tblCarga[PSE Sessão]*tblCarga[Duração (min)]))} | K17: {=IF(B17="","",IFERROR(SUMPRODUCT((tblCarga[Jogador]=B17)*(tblCarga[Microciclo (Nr)]=$H$1)*(tblCarga[Tipo]="Jogo")*tblCarga[Duração (min)]),0))} | L17: {=IF(B17="","",IFERROR(_xlfn.LET(_xlpm.mcs,_xlfn._xlws.SORT(_xlfn.UNIQUE(_xlfn._xlws.FILTER(tblCarga[Microciclo (Nr)],(tblCarga[Jogador]=B17)*(tblCarga[Tipo]="Jogo"))),,,-1),_xlpm.curMC,$H$1,_xlpm.streak,0,IF(ROWS(_xlpm.mcs)=0,0,SUMPRODUCT(--(_xlpm.mcs>=_xlpm.curMC-ROWS(_xlpm.mcs)+1),--(_xlpm.mcs<=_xlpm.curMC)))),0))} | M17: =IF(B17="","",IF(D17>=7,"⚠️ Reduzir carga. Consultar staff médico.",IF(D17>=4,"🔍 Monitorizar. Ajustar volume se necessário.","✅ Manter plano de treino."))) | N17: =IF(B17="","",IF(S17>R17,"▲ "&ROUND(J17,0),IF(S17<R17,"▼ "&ROUND(J17,0),"→ "&ROUND(J17,0)))) | O17: {=IF(B17="","",IFERROR(INDEX(tblCarga[Hooper Index],MATCH(1,(tblCarga[Jogador]=B17)*(tblCarga[Data]=_xlfn.MAXIFS(tblCarga[Data],tblCarga[Jogador],B17,tblCarga[Hooper Index],">0")),0)),"—"))} | P17: {=IF(B17="","",SUMPRODUCT((tblCarga[Jogador]=B17)*(tblCarga[Microciclo (Nr)]=($H$1-3))*(tblCarga[Tipo]="Treino")*tblCarga[PSE Sessão]*tblCarga[Duração (min)]))} | Q17: {=IF(B17="","",SUMPRODUCT((tblCarga[Jogador]=B17)*(tblCarga[Microciclo (Nr)]=($H$1-2))*(tblCarga[Tipo]="Treino")*tblCarga[PSE Sessão]*tblCarga[Duração (min)]))} | R17: {=IF(B17="","",SUMPRODUCT((tblCarga[Jogador]=B17)*(tblCarga[Microciclo (Nr)]=($H$1-1))*(tblCarga[Tipo]="Treino")*tblCarga[PSE Sessão]*tblCarga[Duração (min)]))} | S17: =J17 | T17: =IF(B17="","",IFERROR(TODAY()-_xlfn.MAXIFS(tblCarga[Data],tblCarga[Jogador],B17,tblCarga[Tipo],"Jogo"),"—"))
A18: =IF(B18="","",ROW()-7) | B18: {=IFERROR(IF(INDEX(_xlfn._xlws.SORT(_xlfn.UNIQUE(tblCarga[Jogador])),ROW()-7)=0,"",INDEX(_xlfn._xlws.SORT(_xlfn.UNIQUE(tblCarga[Jogador])),ROW()-7)),"")} | C18: =IF(B18="","",IF(D18>=7,"🔴",IF(D18>=4,"🟡","🟢"))) | D18: =IF(B18="","",_xlfn.LET(_xlpm.acwr,G18,_xlpm.monot,H18,_xlpm.dias,I18,_xlpm.tend,F18,_xlpm.cong,T18,_xlpm.hooper,O18,_xlpm.rACWR,IF(_xlpm.acwr="—",0,IF(OR(_xlpm.acwr>1.5,_xlpm.acwr<0.6),3,IF(OR(_xlpm.acwr>1.3,_xlpm.acwr<0.8),2,IF(_xlpm.acwr<=1.1,0.5,0)))),_xlpm.rMonot,IF(_xlpm.monot>2.5,3,IF(_xlpm.monot>2,2,IF(_xlpm.monot>1.5,1,0))),_xlpm.rDias,IF(_xlpm.dias>14,3,IF(_xlpm.dias>7,2,IF(_xlpm.dias>5,1,0))),_xlpm.rTend,IF(AND(_xlpm.tend="↑",_xlpm.acwr>1.1),1,0),_xlpm.rCong,IF(AND(_xlpm.cong<>"—",_xlpm.cong<4),2,IF(AND(_xlpm.cong<>"—",_xlpm.cong<=5),1,0)),_xlpm.rHooper,IF(AND(_xlpm.hooper<>"—",_xlpm.hooper>=15),1,0),MIN(10,ROUND(_xlpm.rACWR+_xlpm.rMonot+_xlpm.rDias+_xlpm.rTend+_xlpm.rCong+_xlpm.rHooper,0)))) | E18: =IF(B18="","",IF(D18<4,"✅ Sem alertas",_xlfn.LET(_xlpm.acwr,G18,_xlpm.monot,H18,_xlpm.dias,I18,_xlpm.reasons,IF(AND(_xlpm.acwr<>"—",OR(_xlpm.acwr>1.3,_xlpm.acwr<0.8)),"ACWR "&ROUND(_xlpm.acwr,2),"")&IF(AND(_xlpm.monot>2,AND(_xlpm.acwr<>"—",OR(_xlpm.acwr>1.3,_xlpm.acwr<0.8)))," | ","")&IF(_xlpm.monot>2,"Monot "&ROUND(_xlpm.monot,1),"")&IF(AND(_xlpm.dias>7,OR(AND(_xlpm.acwr<>"—",OR(_xlpm.acwr>1.3,_xlpm.acwr<0.8)),_xlpm.monot>2))," | ","")&IF(_xlpm.dias>7,"Vmáx "&_xlpm.dias&"d",""),IF(LEN(_xlpm.reasons)>0,_xlpm.reasons,"Múltiplos fatores")))) | F18: {=IF(B18="","",IFERROR(_xlfn.LET(_xlpm.cur,J18,_xlpm.prev,SUMPRODUCT((tblCarga[Jogador]=B18)*(tblCarga[Microciclo (Nr)]=($H$1-1))*(tblCarga[Tipo]="Treino")*tblCarga[PSE Sessão]*tblCarga[Duração (min)]),_xlpm.delta,(_xlpm.cur-_xlpm.prev)/IF(_xlpm.prev=0,1,_xlpm.prev),IF(_xlpm.delta>0.1,"↑",IF(_xlpm.delta<-0.1,"↓","→"))),"—"))} | G18: =IF(B18="","",IFERROR(J18/AVERAGE(P18,Q18,R18),"—")) | H18: =IF(B18="","",IFERROR(INDEX(Monot_Strain!F$9:F$38,MATCH(B18,Monot_Strain!A$9:A$38,0)),0)) | I18: {=IF(B18="","",IFERROR(TODAY()-MAX(_xlfn._xlws.FILTER(tblCarga[Data],(tblCarga[Jogador]=B18)*(tblCarga[Nº ≥90% Vmáx]>0))),999))} | J18: {=IF(B18="","",SUMPRODUCT((tblCarga[Jogador]=B18)*(tblCarga[Microciclo (Nr)]=$H$1)*(tblCarga[Tipo]="Treino")*tblCarga[PSE Sessão]*tblCarga[Duração (min)]))} | K18: {=IF(B18="","",IFERROR(SUMPRODUCT((tblCarga[Jogador]=B18)*(tblCarga[Microciclo (Nr)]=$H$1)*(tblCarga[Tipo]="Jogo")*tblCarga[Duração (min)]),0))} | L18: {=IF(B18="","",IFERROR(_xlfn.LET(_xlpm.mcs,_xlfn._xlws.SORT(_xlfn.UNIQUE(_xlfn._xlws.FILTER(tblCarga[Microciclo (Nr)],(tblCarga[Jogador]=B18)*(tblCarga[Tipo]="Jogo"))),,,-1),_xlpm.curMC,$H$1,_xlpm.streak,0,IF(ROWS(_xlpm.mcs)=0,0,SUMPRODUCT(--(_xlpm.mcs>=_xlpm.curMC-ROWS(_xlpm.mcs)+1),--(_xlpm.mcs<=_xlpm.curMC)))),0))} | M18: =IF(B18="","",IF(D18>=7,"⚠️ Reduzir carga. Consultar staff médico.",IF(D18>=4,"🔍 Monitorizar. Ajustar volume se necessário.","✅ Manter plano de treino."))) | N18: =IF(B18="","",IF(S18>R18,"▲ "&ROUND(J18,0),IF(S18<R18,"▼ "&ROUND(J18,0),"→ "&ROUND(J18,0)))) | O18: {=IF(B18="","",IFERROR(INDEX(tblCarga[Hooper Index],MATCH(1,(tblCarga[Jogador]=B18)*(tblCarga[Data]=_xlfn.MAXIFS(tblCarga[Data],tblCarga[Jogador],B18,tblCarga[Hooper Index],">0")),0)),"—"))} | P18: {=IF(B18="","",SUMPRODUCT((tblCarga[Jogador]=B18)*(tblCarga[Microciclo (Nr)]=($H$1-3))*(tblCarga[Tipo]="Treino")*tblCarga[PSE Sessão]*tblCarga[Duração (min)]))} | Q18: {=IF(B18="","",SUMPRODUCT((tblCarga[Jogador]=B18)*(tblCarga[Microciclo (Nr)]=($H$1-2))*(tblCarga[Tipo]="Treino")*tblCarga[PSE Sessão]*tblCarga[Duração (min)]))} | R18: {=IF(B18="","",SUMPRODUCT((tblCarga[Jogador]=B18)*(tblCarga[Microciclo (Nr)]=($H$1-1))*(tblCarga[Tipo]="Treino")*tblCarga[PSE Sessão]*tblCarga[Duração (min)]))} | S18: =J18 | T18: =IF(B18="","",IFERROR(TODAY()-_xlfn.MAXIFS(tblCarga[Data],tblCarga[Jogador],B18,tblCarga[Tipo],"Jogo"),"—"))
A19: =IF(B19="","",ROW()-7) | B19: {=IFERROR(IF(INDEX(_xlfn._xlws.SORT(_xlfn.UNIQUE(tblCarga[Jogador])),ROW()-7)=0,"",INDEX(_xlfn._xlws.SORT(_xlfn.UNIQUE(tblCarga[Jogador])),ROW()-7)),"")} | C19: =IF(B19="","",IF(D19>=7,"🔴",IF(D19>=4,"🟡","🟢"))) | D19: =IF(B19="","",_xlfn.LET(_xlpm.acwr,G19,_xlpm.monot,H19,_xlpm.dias,I19,_xlpm.tend,F19,_xlpm.cong,T19,_xlpm.hooper,O19,_xlpm.rACWR,IF(_xlpm.acwr="—",0,IF(OR(_xlpm.acwr>1.5,_xlpm.acwr<0.6),3,IF(OR(_xlpm.acwr>1.3,_xlpm.acwr<0.8),2,IF(_xlpm.acwr<=1.1,0.5,0)))),_xlpm.rMonot,IF(_xlpm.monot>2.5,3,IF(_xlpm.monot>2,2,IF(_xlpm.monot>1.5,1,0))),_xlpm.rDias,IF(_xlpm.dias>14,3,IF(_xlpm.dias>7,2,IF(_xlpm.dias>5,1,0))),_xlpm.rTend,IF(AND(_xlpm.tend="↑",_xlpm.acwr>1.1),1,0),_xlpm.rCong,IF(AND(_xlpm.cong<>"—",_xlpm.cong<4),2,IF(AND(_xlpm.cong<>"—",_xlpm.cong<=5),1,0)),_xlpm.rHooper,IF(AND(_xlpm.hooper<>"—",_xlpm.hooper>=15),1,0),MIN(10,ROUND(_xlpm.rACWR+_xlpm.rMonot+_xlpm.rDias+_xlpm.rTend+_xlpm.rCong+_xlpm.rHooper,0)))) | E19: =IF(B19="","",IF(D19<4,"✅ Sem alertas",_xlfn.LET(_xlpm.acwr,G19,_xlpm.monot,H19,_xlpm.dias,I19,_xlpm.reasons,IF(AND(_xlpm.acwr<>"—",OR(_xlpm.acwr>1.3,_xlpm.acwr<0.8)),"ACWR "&ROUND(_xlpm.acwr,2),"")&IF(AND(_xlpm.monot>2,AND(_xlpm.acwr<>"—",OR(_xlpm.acwr>1.3,_xlpm.acwr<0.8)))," | ","")&IF(_xlpm.monot>2,"Monot "&ROUND(_xlpm.monot,1),"")&IF(AND(_xlpm.dias>7,OR(AND(_xlpm.acwr<>"—",OR(_xlpm.acwr>1.3,_xlpm.acwr<0.8)),_xlpm.monot>2))," | ","")&IF(_xlpm.dias>7,"Vmáx "&_xlpm.dias&"d",""),IF(LEN(_xlpm.reasons)>0,_xlpm.reasons,"Múltiplos fatores")))) | F19: {=IF(B19="","",IFERROR(_xlfn.LET(_xlpm.cur,J19,_xlpm.prev,SUMPRODUCT((tblCarga[Jogador]=B19)*(tblCarga[Microciclo (Nr)]=($H$1-1))*(tblCarga[Tipo]="Treino")*tblCarga[PSE Sessão]*tblCarga[Duração (min)]),_xlpm.delta,(_xlpm.cur-_xlpm.prev)/IF(_xlpm.prev=0,1,_xlpm.prev),IF(_xlpm.delta>0.1,"↑",IF(_xlpm.delta<-0.1,"↓","→"))),"—"))} | G19: =IF(B19="","",IFERROR(J19/AVERAGE(P19,Q19,R19),"—")) | H19: =IF(B19="","",IFERROR(INDEX(Monot_Strain!F$9:F$38,MATCH(B19,Monot_Strain!A$9:A$38,0)),0)) | I19: {=IF(B19="","",IFERROR(TODAY()-MAX(_xlfn._xlws.FILTER(tblCarga[Data],(tblCarga[Jogador]=B19)*(tblCarga[Nº ≥90% Vmáx]>0))),999))} | J19: {=IF(B19="","",SUMPRODUCT((tblCarga[Jogador]=B19)*(tblCarga[Microciclo (Nr)]=$H$1)*(tblCarga[Tipo]="Treino")*tblCarga[PSE Sessão]*tblCarga[Duração (min)]))} | K19: {=IF(B19="","",IFERROR(SUMPRODUCT((tblCarga[Jogador]=B19)*(tblCarga[Microciclo (Nr)]=$H$1)*(tblCarga[Tipo]="Jogo")*tblCarga[Duração (min)]),0))} | L19: {=IF(B19="","",IFERROR(_xlfn.LET(_xlpm.mcs,_xlfn._xlws.SORT(_xlfn.UNIQUE(_xlfn._xlws.FILTER(tblCarga[Microciclo (Nr)],(tblCarga[Jogador]=B19)*(tblCarga[Tipo]="Jogo"))),,,-1),_xlpm.curMC,$H$1,_xlpm.streak,0,IF(ROWS(_xlpm.mcs)=0,0,SUMPRODUCT(--(_xlpm.mcs>=_xlpm.curMC-ROWS(_xlpm.mcs)+1),--(_xlpm.mcs<=_xlpm.curMC)))),0))} | M19: =IF(B19="","",IF(D19>=7,"⚠️ Reduzir carga. Consultar staff médico.",IF(D19>=4,"🔍 Monitorizar. Ajustar volume se necessário.","✅ Manter plano de treino."))) | N19: =IF(B19="","",IF(S19>R19,"▲ "&ROUND(J19,0),IF(S19<R19,"▼ "&ROUND(J19,0),"→ "&ROUND(J19,0)))) | O19: {=IF(B19="","",IFERROR(INDEX(tblCarga[Hooper Index],MATCH(1,(tblCarga[Jogador]=B19)*(tblCarga[Data]=_xlfn.MAXIFS(tblCarga[Data],tblCarga[Jogador],B19,tblCarga[Hooper Index],">0")),0)),"—"))} | P19: {=IF(B19="","",SUMPRODUCT((tblCarga[Jogador]=B19)*(tblCarga[Microciclo (Nr)]=($H$1-3))*(tblCarga[Tipo]="Treino")*tblCarga[PSE Sessão]*tblCarga[Duração (min)]))} | Q19: {=IF(B19="","",SUMPRODUCT((tblCarga[Jogador]=B19)*(tblCarga[Microciclo (Nr)]=($H$1-2))*(tblCarga[Tipo]="Treino")*tblCarga[PSE Sessão]*tblCarga[Duração (min)]))} | R19: {=IF(B19="","",SUMPRODUCT((tblCarga[Jogador]=B19)*(tblCarga[Microciclo (Nr)]=($H$1-1))*(tblCarga[Tipo]="Treino")*tblCarga[PSE Sessão]*tblCarga[Duração (min)]))} | S19: =J19 | T19: =IF(B19="","",IFERROR(TODAY()-_xlfn.MAXIFS(tblCarga[Data],tblCarga[Jogador],B19,tblCarga[Tipo],"Jogo"),"—"))
